Workbook

Sheet Cover
B2: 40 MW Hyperscale-Ready Data Centre
B3: Behind-the-Meter 90 MWp Solar PV + 60 MWh BESS | Greater Accra, Ghana
B4: Project Finance Model — Reporting Currency: USD
B6: ACTIVE SCENARIO | D6: Scenario Key Changes
B7: Base Case | D7: Best: Utilisation +10pts, Capacity chg +8%, Solar yield +7%, Capex -7%, Rate -0.75%, PUE 1.18 | Worst: Utilisation -15pts, Capacity chg -10%, Solar yield=P90, Capex +12%, Rate +1.25%, PUE 1.35, higher curtailment
B9: KEY OUTPUTS (live — updates with Scenario)
B10: EQUITY IRR | D10: EQUITY NPV @12% | F10: EQUITY MULTIPLE | H10: MIN DSCR
B11: ='Outputs & Dashboard'!C5 -> -0.11516319 | D11: ='Outputs & Dashboard'!C6 -> -2.6884206e+08 | F11: ='Outputs & Dashboard'!C7 -> 0.26550096 | H11: ='Outputs & Dashboard'!C8 -> 1.35
B13: AVG DSCR | D13: GEARING (ACTUAL) | F13: TOTAL PROJECT COST | H13: COD
B14: ='Outputs & Dashboard'!C9 -> 1.35 | D14: ='Outputs & Dashboard'!C10 -> 0.35830318 | F14: ='Outputs & Dashboard'!C11 -> 5.0785848e+08 | H14: ='Outputs & Dashboard'!C12 -> 46935
B21: Project Summary
B22: IT Capacity | D22: 40 MW
B23: Design PUE (Base) | D23: 1.25
B24: Construction Period | D24: 24 months
B25: Target COD | D25: 1 July 2028
B26: Offtake Structure | D26: 15-yr take-or-pay, 85% contracted / 15% spot
B27: Solar PV | D27: 90 MWp single-axis tracking
B28: BESS | D28: 60 MWh (4-hr), 90% RTE
B29: Senior Debt | D29: Sculpted to min. 1.35x DSCR, target 65% gearing
B31: Navigation: Assumptions | Timing & Calendar | Construction | Operations | Debt & Financing | Cash Flow Waterfall | Reserves | Outputs & Dashboard | Sensitivities & Scenarios | Checks-Audit | Appendix-Glossary | Charts

Sheet Assumptions
B1: ASSUMPTIONS — All Base/Best/Worst cases editable (blue). "Active" column drives the entire model.
B3: Active Scenario: | C3: =Cover!$B$7 -> Base Case
B5: Assumption | C5: Base Case | D5: Best Case | E5: Worst Case | F5: Active | G5: Notes / Source
A8: DATA CENTRE
B9: IT Capacity (MW) | C9: 40 | D9: 40 | E9: 40 | F9: =INDEX(C9:E9,MATCH($C$3,{"Base Case","Best Case","Worst Case"},0)) -> 40 | G9: Fixed nameplate IT capacity — user brief
B10: Design PUE | C10: 1.25 | D10: 1.18 | E10: 1.35 | F10: =INDEX(C10:E10,MATCH($C$3,{"Base Case","Best Case","Worst Case"},0)) -> 1.25 | G10: Best/Worst per brief
B11: Utilisation — Year 1 | C11: 0.55 | D11: 0.65 | E11: 0.4 | F11: =INDEX(C11:E11,MATCH($C$3,{"Base Case","Best Case","Worst Case"},0)) -> 0.55 | G11: Best +10pts / Worst -15pts vs Base
B12: Utilisation — Year 2 | C12: 0.75 | D12: 0.85 | E12: 0.6 | F12: =INDEX(C12:E12,MATCH($C$3,{"Base Case","Best Case","Worst Case"},0)) -> 0.75 | G12: Best +10pts / Worst -15pts vs Base
B13: Utilisation — Year 3+ | C13: 0.9 | D13: 1 | E13: 0.75 | F13: =INDEX(C13:E13,MATCH($C$3,{"Base Case","Best Case","Worst Case"},0)) -> 0.9 | G13: Best +10pts / Worst -15pts vs Base
B14: Capacity Charge ($/kW-month) | C14: 18.5 | D14: 19.98 | E14: 16.65 | F14: =INDEX(C14:E14,MATCH($C$3,{"Base Case","Best Case","Worst Case"},0)) -> 18.5 | G14: Best +8% / Worst -10%
B15: Energy Charge ($/kWh) | C15: 0.155 | D15: 0.155 | E15: 0.155 | F15: =INDEX(C15:E15,MATCH($C$3,{"Base Case","Best Case","Worst Case"},0)) -> 0.155 | G15: Set above blended renewable+grid-backup supply cost (~$0.06-0.14/kWh) plus margin, per brief; flat — not specified to vary by scenario
B16: Take-or-Pay Contracted Share | C16: 0.85 | D16: 0.85 | E16: 0.85 | F16: =INDEX(C16:E16,MATCH($C$3,{"Base Case","Best Case","Worst Case"},0)) -> 0.85 | G16: 85% take-or-pay per brief; residual on spot
B17: Grid Backup / Top-Up Price ($/kWh) | C17: 0.14 | D17: 0.14 | E17: 0.16 | F17: =INDEX(C17:E17,MATCH($C$3,{"Base Case","Best Case","Worst Case"},0)) -> 0.14 | G17: Shortfall energy not met by dedicated renewables
A19: RENEWABLE POWER SYSTEM (90 MWp Solar + 60 MWh BESS)
B20: Solar Capacity (MWp) | C20: 90 | D20: 90 | E20: 90 | F20: =INDEX(C20:E20,MATCH($C$3,{"Base Case","Best Case","Worst Case"},0)) -> 90 | G20: Single-axis tracking — fixed
B21: Specific Yield P50 (kWh/kWp/yr) | C21: 1680 | D21: 1797.6 | E21: 1520 | F21: =INDEX(C21:E21,MATCH($C$3,{"Base Case","Best Case","Worst Case"},0)) -> 1680 | G21: Best +7% / Worst = P90 (1,520)
B22: Annual Degradation | C22: 0.005 | D22: 0.005 | E22: 0.005 | F22: =INDEX(C22:E22,MATCH($C$3,{"Base Case","Best Case","Worst Case"},0)) -> 0.005 | G22: Flat across scenarios
B23: Curtailment / Clipping | C23: 0.03 | D23: 0.025 | E23: 0.06 | F23: =INDEX(C23:E23,MATCH($C$3,{"Base Case","Best Case","Worst Case"},0)) -> 0.03 | G23: Worst: higher curtailment per brief
B24: BESS Capacity (MWh) | C24: 60 | D24: 60 | E24: 60 | F24: =INDEX(C24:E24,MATCH($C$3,{"Base Case","Best Case","Worst Case"},0)) -> 60 | G24: 4-hr equivalent — fixed
B25: BESS Round-Trip Efficiency | C25: 0.9 | D25: 0.9 | E25: 0.9 | F25: =INDEX(C25:E25,MATCH($C$3,{"Base Case","Best Case","Worst Case"},0)) -> 0.9 | G25: Flat across scenarios
B26: Share of Generation Cycled via BESS | C26: 0.3 | D26: 0.3 | E26: 0.3 | F26: =INDEX(C26:E26,MATCH($C$3,{"Base Case","Best Case","Worst Case"},0)) -> 0.3 | G26: Modelling assumption for RTE loss netting
B27: BESS Life (years, pre-augmentation) | C27: 15 | D27: 15 | E27: 15 | F27: =INDEX(C27:E27,MATCH($C$3,{"Base Case","Best Case","Worst Case"},0)) -> 15 | G27: With augmentation per brief
B28: BESS Augmentation Capex (% of RE Capex) | C28: 0.2 | D28: 0.2 | E28: 0.2 | F28: =INDEX(C28:E28,MATCH($C$3,{"Base Case","Best Case","Worst Case"},0)) -> 0.2 | G28: Modelling assumption — mid-life augmentation event
B29: Augmentation Event — Operating Period # | C29: 16 | D29: 16 | E29: 16 | F29: =INDEX(C29:E29,MATCH($C$3,{"Base Case","Best Case","Worst Case"},0)) -> 16 | G29: ~Year 8 (mid-BESS-life)
A31: COSTS
B32: Data Centre Capex ($m per IT MW) | C32: 9.5 | D32: 8.835 | E32: 10.64 | F32: =INDEX(C32:E32,MATCH($C$3,{"Base Case","Best Case","Worst Case"},0)) -> 9.5 | G32: Best -7% / Worst +12%
B33: Solar + BESS Capex ($m per MWp) | C33: 1.15 | D33: 1.0695 | E33: 1.288 | F33: =INDEX(C33:E33,MATCH($C$3,{"Base Case","Best Case","Worst Case"},0)) -> 1.15 | G33: Best -7% / Worst +12%
B34: Data Centre O&M ($k per IT MW p.a.) | C34: 180 | D34: 180 | E34: 180 | F34: =INDEX(C34:E34,MATCH($C$3,{"Base Case","Best Case","Worst Case"},0)) -> 180 | G34: Flat across scenarios
B35: Solar+BESS O&M ($k per MW p.a.) | C35: 18 | D35: 18 | E35: 18 | F35: =INDEX(C35:E35,MATCH($C$3,{"Base Case","Best Case","Worst Case"},0)) -> 18 | G35: Flat across scenarios
B36: Land Lease & Security ($k p.a.) | C36: 350 | D36: 350 | E36: 350 | F36: =INDEX(C36:E36,MATCH($C$3,{"Base Case","Best Case","Worst Case"},0)) -> 350 | G36: Flat across scenarios
A38: FINANCING
B39: Debt Tenor (years from COD) | C39: 15 | D39: 15 | E39: 15 | F39: =INDEX(C39:E39,MATCH($C$3,{"Base Case","Best Case","Worst Case"},0)) -> 15 | G39: Fixed
B40: All-in Interest Rate | C40: 0.0775 | D40: 0.07 | E40: 0.09 | F40: =INDEX(C40:E40,MATCH($C$3,{"Base Case","Best Case","Worst Case"},0)) -> 0.0775 | G40: Best -0.75pts / Worst +1.25pts
B41: Upfront Fee | C41: 0.0175 | D41: 0.0175 | E41: 0.0175 | F41: =INDEX(C41:E41,MATCH($C$3,{"Base Case","Best Case","Worst Case"},0)) -> 0.0175 | G41: Flat across scenarios
B42: DSRA (months of debt service) | C42: 6 | D42: 6 | E42: 6 | F42: =INDEX(C42:E42,MATCH($C$3,{"Base Case","Best Case","Worst Case"},0)) -> 6 | G42: Flat across scenarios
B43: Target Minimum DSCR | C43: 1.35 | D43: 1.35 | E43: 1.35 | F43: =INDEX(C43:E43,MATCH($C$3,{"Base Case","Best Case","Worst Case"},0)) -> 1.35 | G43: Sculpting target
B44: Target Gearing | C44: 0.65 | D44: 0.65 | E44: 0.65 | F44: =INDEX(C44:E44,MATCH($C$3,{"Base Case","Best Case","Worst Case"},0)) -> 0.65 | G44: Cap on debt as % of hard capex
B45: Circularity Breaker (1=on) | C45: 1 | D45: 1 | E45: 1 | F45: =INDEX(C45:E45,MATCH($C$3,{"Base Case","Best Case","Worst Case"},0)) -> 1 | G45: ON: tax excludes interest deductibility to avoid circularity without iterative calc. Set to 0 and enable Excel iterative calc for full precision.
A47: MACRO & TAX
B48: USD Inflation | C48: 0.022 | D48: 0.022 | E48: 0.022 | F48: =INDEX(C48:E48,MATCH($C$3,{"Base Case","Best Case","Worst Case"},0)) -> 0.022 | G48: Flat across scenarios
...

Sheet Timing & Calendar
B1: TIMING & CALENDAR — Master date axis driving Construction, Operations, Debt, Waterfall and Reserves
A3: CONSTRUCTION CALENDAR (Monthly, Month 1 = Construction Start)
B4: Month # | C4: 1 | D4: 2 | E4: 3 | F4: 4 | G4: 5 | H4: 6 | I4: 7 | J4: 8 | K4: 9 | L4: 10 | M4: 11 | N4: 12 | O4: 13 | P4: 14 | Q4: 15 | R4: 16 | S4: 17 | T4: 18 | U4: 19 | V4: 20 | W4: 21 | X4: 22 | Y4: 23 | Z4: 24
B5: Month Start Date | C5: =EDATE(Assumptions!$C$55,0) -> 46204 | D5: =EDATE(C5,1) -> 46235 | E5: =EDATE(D5,1) -> 46266 | F5: =EDATE(E5,1) -> 46296 | G5: =EDATE(F5,1) -> 46327 | H5: =EDATE(G5,1) -> 46357 | I5: =EDATE(H5,1) -> 46388 | J5: =EDATE(I5,1) -> 46419 | K5: =EDATE(J5,1) -> 46447 | ... Z5: =EDATE(Y5,1) -> 46905
B6: Month End Date | C6: =EDATE(C5,1)-1 -> 46234 | D6: =EDATE(D5,1)-1 -> 46265 | E6: =EDATE(E5,1)-1 -> 46295 | F6: =EDATE(F5,1)-1 -> 46326 | G6: =EDATE(G5,1)-1 -> 46356 | H6: =EDATE(H5,1)-1 -> 46387 | I6: =EDATE(I5,1)-1 -> 46418 | J6: =EDATE(J5,1)-1 -> 46446 | ... Z6: =EDATE(Z5,1)-1 -> 46934
B7: Days in Month | C7: =C6-C5+1 -> 31 | D7: =D6-D5+1 -> 31 | E7: =E6-E5+1 -> 30 | F7: =F6-F5+1 -> 31 | G7: =G6-G5+1 -> 30 | H7: =H6-H5+1 -> 31 | I7: =I6-I5+1 -> 31 | J7: =J6-J5+1 -> 28 | ... Z7: =Z6-Z5+1 -> 30
A9: OPERATIONS CALENDAR (Semi-Annual, Period 1 begins at COD)
B10: Period # | C10: 1 | D10: 2 | E10: 3 | F10: 4 | G10: 5 | H10: 6 | I10: 7 | J10: 8 | K10: 9 | L10: 10 | M10: 11 | N10: 12 | O10: 13 | P10: 14 | Q10: 15 | R10: 16 | S10: 17 | T10: 18 | U10: 19 | V10: 20 | W10: 21 | X10: 22 | Y10: 23 | Z10: 24 | AA10: 25 | AB10: 26 | AC10: 27 | AD10: 28 | AE10: 29 | AF10: 30
B11: Period Start Date | C11: =Assumptions!$C$56 -> 46935 | D11: =EDATE(C11,6) -> 47119 | E11: =EDATE(D11,6) -> 47300 | F11: =EDATE(E11,6) -> 47484 | G11: =EDATE(F11,6) -> 47665 | H11: =EDATE(G11,6) -> 47849 | I11: =EDATE(H11,6) -> 48030 | J11: =EDATE(I11,6) -> 48214 | K11: =EDATE(J11,6) -> 48396 | ... AF11: =EDATE(AE11,6) -> 52232
B12: Period End Date | C12: =EDATE(C11,6)-1 -> 47118 | D12: =EDATE(D11,6)-1 -> 47299 | E12: =EDATE(E11,6)-1 -> 47483 | F12: =EDATE(F11,6)-1 -> 47664 | G12: =EDATE(G11,6)-1 -> 47848 | H12: =EDATE(H11,6)-1 -> 48029 | I12: =EDATE(I11,6)-1 -> 48213 | J12: =EDATE(J11,6)-1 -> 48395 | ... AF12: =EDATE(AF11,6)-1 -> 52412
B13: Months in Period | C13: 6 | D13: 6 | E13: 6 | F13: 6 | G13: 6 | H13: 6 | I13: 6 | J13: 6 | K13: 6 | L13: 6 | M13: 6 | N13: 6 | O13: 6 | P13: 6 | Q13: 6 | R13: 6 | S13: 6 | T13: 6 | U13: 6 | V13: 6 | W13: 6 | X13: 6 | Y13: 6 | Z13: 6 | AA13: 6 | AB13: 6 | AC13: 6 | AD13: 6 | AE13: 6 | AF13: 6
B14: Operating Year # | C14: =ROUNDUP(1/2,0) -> 1 | D14: =ROUNDUP(2/2,0) -> 1 | E14: =ROUNDUP(3/2,0) -> 2 | F14: =ROUNDUP(4/2,0) -> 2 | G14: =ROUNDUP(5/2,0) -> 3 | H14: =ROUNDUP(6/2,0) -> 3 | I14: =ROUNDUP(7/2,0) -> 4 | J14: =ROUNDUP(8/2,0) -> 4 | K14: =ROUNDUP(9/2,0) -> 5 | L14: =ROUNDUP(10/2,0) -> 5 | M14: =ROUNDUP(11/2,0) -> 6 | N14: =ROUNDUP(12/2,0) -> 6 | O14: =ROUNDUP(13/2,0) -> 7 | P14: =ROUNDUP(14/2,0) -> 7 | Q14: =ROUNDUP(15/2,0) -> 8 | R14: =ROUNDUP(16/2,0) -> 8 | S14: =ROUNDUP(17/2,0) -> 9 | T14: =ROUNDUP(18/2,0) -> 9 | U14: =ROUNDUP(19/2,0) -> 10 | V14: =ROUNDUP(20/2,0) -> 10 | W14: =ROUNDUP(21/2,0) -> 11 | X14: =ROUNDUP(22/2,0) -> 11 | Y14: =ROUNDUP(23/2,0) -> 12 | Z14: =ROUNDUP(24/2,0) -> 12 | AA14: =ROUNDUP(25/2,0) -> 13 | AB14: =ROUNDUP(26/2,0) -> 13 | AC14: =ROUNDUP(27/2,0) -> 14 | AD14: =ROUNDUP(28/2,0) -> 14 | AE14: =ROUNDUP(29/2,0) -> 15 | AF14: =ROUNDUP(30/2,0) -> 15
B15: Years Since COD (period start) | C15: =(C11-Assumptions!$C$56)/365.25 -> 0 | D15: =(D11-Assumptions!$C$56)/365.25 -> 0.50376454 | E15: =(E11-Assumptions!$C$56)/365.25 -> 0.99931554 | F15: =(F11-Assumptions!$C$56)/365.25 -> 1.5030801 | G15: =(G11-Assumptions!$C$56)/365.25 -> 1.9986311 | H15: =(H11-Assumptions!$C$56)/365.25 -> 2.5023956 | I15: =(I11-Assumptions!$C$56)/365.25 -> 2.9979466 | J15: =(J11-Assumptions!$C$56)/365.25 -> 3.5017112 | ... AF15: =(AF11-Assumptions!$C$56)/365.25 -> 14.502396
B16: Inflation Escalation Factor | C16: =(1+Assumptions!$F$48)^C15 -> 1 | D16: =(1+Assumptions!$F$48)^D15 -> 1.011023 | E16: =(1+Assumptions!$F$48)^E15 -> 1.0219848 | F16: =(1+Assumptions!$F$48)^F15 -> 1.0332501 | G16: =(1+Assumptions!$F$48)^G15 -> 1.0444529 | H16: =(1+Assumptions!$F$48)^H15 -> 1.0559659 | I16: =(1+Assumptions!$F$48)^I15 -> 1.0674149 | J16: =(1+Assumptions!$F$48)^J15 -> 1.079181 | ... AF16: =(1+Assumptions!$F$48)^AF15 -> 1.3710732
B17: Solar Degradation Factor | C17: =(1-Assumptions!$F$22)^C15 -> 1 | D17: =(1-Assumptions!$F$22)^D15 -> 0.99747804 | E17: =(1-Assumptions!$F$22)^E15 -> 0.99500341 | F17: =(1-Assumptions!$F$22)^F15 -> 0.99249406 | G17: =(1-Assumptions!$F$22)^G15 -> 0.99003179 | H17: =(1-Assumptions!$F$22)^H15 -> 0.98753498 | I17: =(1-Assumptions!$F$22)^I15 -> 0.98508501 | J17: =(1-Assumptions!$F$22)^J15 -> 0.98260067 | ... AF17: =(1-Assumptions!$F$22)^AF15 -> 0.92988546

Sheet Construction
B1: CONSTRUCTION — 24-Month Capex Drawdown, S-Curve, IDC & Sources and Uses
A3: PROJECT HARD CAPEX (from Assumptions — Active scenario)
B4: Data Centre Capex ($) | C4: =Assumptions!$F$32*1000000*Assumptions!$F$9 -> 380000000
B5: Renewable (Solar+BESS) Capex ($) | C5: =Assumptions!$F$33*1000000*Assumptions!$F$20 -> 103500000
B6: Total Hard Capex ($) | C6: =C4+C5 -> 483500000
A8: CAPEX S-CURVE DRAWDOWN (formula-driven parabola: weight(t) ∝ t×(25-t), normalised to 100%)
B9: Month # | C9: ='Timing & Calendar'!C$4 -> 1 | D9: ='Timing & Calendar'!D$4 -> 2 | E9: ='Timing & Calendar'!E$4 -> 3 | F9: ='Timing & Calendar'!F$4 -> 4 | G9: ='Timing & Calendar'!G$4 -> 5 | H9: ='Timing & Calendar'!H$4 -> 6 | I9: ='Timing & Calendar'!I$4 -> 7 | J9: ='Timing & Calendar'!J$4 -> 8 | ... Z9: ='Timing & Calendar'!Z$4 -> 24
B10: Raw S-Curve Weight [t*(25-t)] | C10: =1*(25-1) -> 24 | D10: =2*(25-2) -> 46 | E10: =3*(25-3) -> 66 | F10: =4*(25-4) -> 84 | G10: =5*(25-5) -> 100 | H10: =6*(25-6) -> 114 | I10: =7*(25-7) -> 126 | J10: =8*(25-8) -> 136 | K10: =9*(25-9) -> 144 | L10: =10*(25-10) -> 150 | M10: =11*(25-11) -> 154 | N10: =12*(25-12) -> 156 | O10: =13*(25-13) -> 156 | P10: =14*(25-14) -> 154 | Q10: =15*(25-15) -> 150 | R10: =16*(25-16) -> 144 | S10: =17*(25-17) -> 136 | T10: =18*(25-18) -> 126 | U10: =19*(25-19) -> 114 | V10: =20*(25-20) -> 100 | W10: =21*(25-21) -> 84 | X10: =22*(25-22) -> 66 | Y10: =23*(25-23) -> 46 | Z10: =24*(25-24) -> 24
B11: Normalised Draw Weight (%) | C11: =C10/SUM(C10:Z10) -> 0.0092307692 | D11: =D10/SUM(C10:Z10) -> 0.017692308 | E11: =E10/SUM(C10:Z10) -> 0.025384615 | F11: =F10/SUM(C10:Z10) -> 0.032307692 | G11: =G10/SUM(C10:Z10) -> 0.038461538 | H11: =H10/SUM(C10:Z10) -> 0.043846154 | I11: =I10/SUM(C10:Z10) -> 0.048461538 | J11: =J10/SUM(C10:Z10) -> 0.052307692 | K11: =K10/SUM(C10:Z10) -> 0.055384615 | L11: =L10/SUM(C10:Z10) -> 0.057692308 | M11: =M10/SUM(C10:Z10) -> 0.059230769 | N11: =N10/SUM(C10:Z10) -> 0.06 | O11: =O10/SUM(C10:Z10) -> 0.06 | P11: =P10/SUM(C10:Z10) -> 0.059230769 | Q11: =Q10/SUM(C10:Z10) -> 0.057692308 | R11: =R10/SUM(C10:Z10) -> 0.055384615 | S11: =S10/SUM(C10:Z10) -> 0.052307692 | T11: =T10/SUM(C10:Z10) -> 0.048461538 | U11: =U10/SUM(C10:Z10) -> 0.043846154 | V11: =V10/SUM(C10:Z10) -> 0.038461538 | W11: =W10/SUM(C10:Z10) -> 0.032307692 | X11: =X10/SUM(C10:Z10) -> 0.025384615 | Y11: =Y10/SUM(C10:Z10) -> 0.017692308 | Z11: =Z10/SUM(C10:Z10) -> 0.0092307692
B12: DC Capex Draw ($) | C12: =$C$4*C11 -> 3507692.3 | D12: =$C$4*D11 -> 6723076.9 | E12: =$C$4*E11 -> 9646153.8 | F12: =$C$4*F11 -> 12276923 | G12: =$C$4*G11 -> 14615385 | H12: =$C$4*H11 -> 16661538 | I12: =$C$4*I11 -> 18415385 | J12: =$C$4*J11 -> 19876923 | ... Z12: =$C$4*Z11 -> 3507692.3
B13: Renewable Capex Draw ($) | C13: =$C$5*C11 -> 955384.62 | D13: =$C$5*D11 -> 1831153.8 | E13: =$C$5*E11 -> 2627307.7 | F13: =$C$5*F11 -> 3343846.2 | G13: =$C$5*G11 -> 3980769.2 | H13: =$C$5*H11 -> 4538076.9 | I13: =$C$5*I11 -> 5015769.2 | J13: =$C$5*J11 -> 5413846.2 | ... Z13: =$C$5*Z11 -> 955384.62
B14: Total Capex Draw ($) | C14: =C12+C13 -> 4463076.9 | D14: =D12+D13 -> 8554230.8 | E14: =E12+E13 -> 12273462 | F14: =F12+F13 -> 15620769 | G14: =G12+G13 -> 18596154 | H14: =H12+H13 -> 21199615 | I14: =I12+I13 -> 23431154 | J14: =J12+J13 -> 25290769 | ... Z14: =Z12+Z13 -> 4463076.9
B15: Cumulative Capex Draw ($) | C15: =C14 -> 4463076.9 | D15: =C15+D14 -> 13017308 | E15: =D15+E14 -> 25290769 | F15: =E15+F14 -> 40911538 | G15: =F15+G14 -> 59507692 | H15: =G15+H14 -> 80707308 | I15: =H15+I14 -> 1.0413846e+08 | J15: =I15+J14 -> 1.2942923e+08 | K15: =J15+K14 -> 1.5620769e+08 | ... Z15: =Y15+Z14 -> 483500000
A17: DEBT & EQUITY DRAWDOWN (pro-rata at Target Gearing on Hard Capex; IDC & Fees equity-funded top-up)
B18: Debt Drawdown ($) [pro-rata at ratio = Final Sculpted Debt / Hard Capex] | C18: =C14*('Debt & Financing'!$C$17/$C$6) -> 1599134.7 | D18: =D14*('Debt & Financing'!$C$17/$C$6) -> 3065008.1 | E18: =E14*('Debt & Financing'!$C$17/$C$6) -> 4397620.3 | F18: =F14*('Debt & Financing'!$C$17/$C$6) -> 5596971.3 | G18: =G14*('Debt & Financing'!$C$17/$C$6) -> 6663061.1 | H18: =H14*('Debt & Financing'!$C$17/$C$6) -> 7595889.7 | I18: =I14*('Debt & Financing'!$C$17/$C$6) -> 8395457 | J18: =J14*('Debt & Financing'!$C$17/$C$6) -> 9061763.1 | ... Z18: =Z14*('Debt & Financing'!$C$17/$C$6) -> 1599134.7
B19: Cumulative Debt Drawn ($) | C19: =C18 -> 1599134.7 | D19: =C19+D18 -> 4664142.8 | E19: =D19+E18 -> 9061763.1 | F19: =E19+F18 -> 14658734 | G19: =F19+G18 -> 21321796 | H19: =G19+H18 -> 28917685 | I19: =H19+I18 -> 37313142 | J19: =I19+J18 -> 46374905 | K19: =J19+K18 -> 55969713 | ... Z19: =Y19+Z18 -> 1.7323959e+08
B20: IDC for Month (on opening cum. debt balance) ($) | C20: =(0)*Assumptions!$F$40/12 -> 0 | D20: =(C19)*Assumptions!$F$40/12 -> 10327.745 | E20: =(D19)*Assumptions!$F$40/12 -> 30122.589 | F20: =(E19)*Assumptions!$F$40/12 -> 58523.887 | G20: =(F19)*Assumptions!$F$40/12 -> 94670.994 | H20: =(G19)*Assumptions!$F$40/12 -> 137703.26 | I20: =(H19)*Assumptions!$F$40/12 -> 186760.05 | J20: =(I19)*Assumptions!$F$40/12 -> 240980.71 | K20: =(J19)*Assumptions!$F$40/12 -> 299504.6 | ... Z20: =(Y19)*Assumptions!$F$40/12 -> 1108511.3
B21: Cumulative IDC ($) | C21: =C20 -> 0 | D21: =C21+D20 -> 10327.745 | E21: =D21+E20 -> 40450.334 | F21: =E21+F20 -> 98974.221 | G21: =F21+G20 -> 193645.21 | H21: =G21+H20 -> 331348.48 | I21: =H21+I20 -> 518108.53 | J21: =I21+J20 -> 759089.24 | K21: =J21+K20 -> 1058593.8 | ... Z21: =Y21+Z20 -> 12866649
B22: Equity Drawdown ($) [Total draw less Debt Drawdown, plus IDC] | C22: =C14-C18+C20 -> 2863942.3 | D22: =D14-D18+D20 -> 5499550.4 | E22: =E14-E18+E20 -> 7905963.8 | F22: =F14-F18+F20 -> 10082322 | G22: =G14-G18+G20 -> 12027764 | H22: =H14-H18+H20 -> 13741429 | I22: =I14-I18+I20 -> 15222457 | J22: =J14-J18+J20 -> 16469987 | ... Z22: =Z14-Z18+Z20 -> 3972453.5
A24: SOURCES AND USES (at COD)
B25: USES | D25: SOURCES
B26: Data Centre Capex | C26: =C4 -> 380000000 | D26: Senior Debt Drawn | E26: =Z19 -> 1.7323959e+08
B27: Renewable Capex | C27: =C5 -> 103500000 | D27: Equity Contributed (Capex + IDC) | E27: =SUM(C22:Z22) -> 3.2312706e+08
B28: Interest During Construction (IDC) | C28: =Z21 -> 12866649 | D28: Additional Equity — Fees & Initial DSRA | E28: =C29+C30 -> 11491827
B29: Upfront Financing Fee | C29: =Z19*Assumptions!$F$41 -> 3031692.8
B30: Initial DSRA Funding | C30: ='Debt & Financing'!C36 -> 8460134.1
B31: TOTAL USES | C31: =SUM(C26:C30) -> 5.0785848e+08 | D31: TOTAL SOURCES | E31: =E26+E27+E28 -> 5.0785848e+08
B32: CHECK: Sources = Uses | C32: =IF(ABS(C31-E31)<1,"OK","ERROR") -> OK

Sheet Operations
B1: OPERATIONS — Data Centre Revenue, Renewable Generation + BESS, Opex, EBITDA (30 Semi-Annual Periods)
A3: PERIOD REFERENCE
B4: Period # | C4: ='Timing & Calendar'!C$10 -> 1 | D4: ='Timing & Calendar'!D$10 -> 2 | E4: ='Timing & Calendar'!E$10 -> 3 | F4: ='Timing & Calendar'!F$10 -> 4 | G4: ='Timing & Calendar'!G$10 -> 5 | H4: ='Timing & Calendar'!H$10 -> 6 | I4: ='Timing & Calendar'!I$10 -> 7 | J4: ='Timing & Calendar'!J$10 -> 8 | ... AF4: ='Timing & Calendar'!AF$10 -> 30
B5: Operating Year # | C5: ='Timing & Calendar'!C$14 -> 1 | D5: ='Timing & Calendar'!D$14 -> 1 | E5: ='Timing & Calendar'!E$14 -> 2 | F5: ='Timing & Calendar'!F$14 -> 2 | G5: ='Timing & Calendar'!G$14 -> 3 | H5: ='Timing & Calendar'!H$14 -> 3 | I5: ='Timing & Calendar'!I$14 -> 4 | J5: ='Timing & Calendar'!J$14 -> 4 | ... AF5: ='Timing & Calendar'!AF$14 -> 15
B6: Escalation Factor | C6: ='Timing & Calendar'!C$16 -> 1 | D6: ='Timing & Calendar'!D$16 -> 1.011023 | E6: ='Timing & Calendar'!E$16 -> 1.0219848 | F6: ='Timing & Calendar'!F$16 -> 1.0332501 | G6: ='Timing & Calendar'!G$16 -> 1.0444529 | H6: ='Timing & Calendar'!H$16 -> 1.0559659 | I6: ='Timing & Calendar'!I$16 -> 1.0674149 | J6: ='Timing & Calendar'!J$16 -> 1.079181 | ... AF6: ='Timing & Calendar'!AF$16 -> 1.3710732
B7: Degradation Factor (Solar) | C7: ='Timing & Calendar'!C$17 -> 1 | D7: ='Timing & Calendar'!D$17 -> 0.99747804 | E7: ='Timing & Calendar'!E$17 -> 0.99500341 | F7: ='Timing & Calendar'!F$17 -> 0.99249406 | G7: ='Timing & Calendar'!G$17 -> 0.99003179 | H7: ='Timing & Calendar'!H$17 -> 0.98753498 | I7: ='Timing & Calendar'!I$17 -> 0.98508501 | J7: ='Timing & Calendar'!J$17 -> 0.98260067 | ... AF7: ='Timing & Calendar'!AF$17 -> 0.92988546
A9: DATA CENTRE — UTILISATION & DEMAND
B10: Utilisation % | C10: =IF(C5=1,Assumptions!$F$11,IF(C5=2,Assumptions!$F$12,Assumptions!$F$13)) -> 0.55 | D10: =IF(D5=1,Assumptions!$F$11,IF(D5=2,Assumptions!$F$12,Assumptions!$F$13)) -> 0.55 | E10: =IF(E5=1,Assumptions!$F$11,IF(E5=2,Assumptions!$F$12,Assumptions!$F$13)) -> 0.75 | F10: =IF(F5=1,Assumptions!$F$11,IF(F5=2,Assumptions!$F$12,Assumptions!$F$13)) -> 0.75 | G10: =IF(G5=1,Assumptions!$F$11,IF(G5=2,Assumptions!$F$12,Assumptions!$F$13)) -> 0.9 | H10: =IF(H5=1,Assumptions!$F$11,IF(H5=2,Assumptions!$F$12,Assumptions!$F$13)) -> 0.9 | I10: =IF(I5=1,Assumptions!$F$11,IF(I5=2,Assumptions!$F$12,Assumptions!$F$13)) -> 0.9 | J10: =IF(J5=1,Assumptions!$F$11,IF(J5=2,Assumptions!$F$12,Assumptions!$F$13)) -> 0.9 | ... AF10: =IF(AF5=1,Assumptions!$F$11,IF(AF5=2,Assumptions!$F$12,Assumptions!$F$13)) -> 0.9
B11: IT Load (MW) | C11: =Assumptions!$F$9*C10 -> 22 | D11: =Assumptions!$F$9*D10 -> 22 | E11: =Assumptions!$F$9*E10 -> 30 | F11: =Assumptions!$F$9*F10 -> 30 | G11: =Assumptions!$F$9*G10 -> 36 | H11: =Assumptions!$F$9*H10 -> 36 | I11: =Assumptions!$F$9*I10 -> 36 | J11: =Assumptions!$F$9*J10 -> 36 | ... AF11: =Assumptions!$F$9*AF10 -> 36
B12: Facility Load incl. PUE (MW) | C12: =C11*Assumptions!$F$10 -> 27.5 | D12: =D11*Assumptions!$F$10 -> 27.5 | E12: =E11*Assumptions!$F$10 -> 37.5 | F12: =F11*Assumptions!$F$10 -> 37.5 | G12: =G11*Assumptions!$F$10 -> 45 | H12: =H11*Assumptions!$F$10 -> 45 | I12: =I11*Assumptions!$F$10 -> 45 | J12: =J11*Assumptions!$F$10 -> 45 | ... AF12: =AF11*Assumptions!$F$10 -> 45
B13: Facility Energy Demand (MWh) | C13: =C12*182.625*24 -> 120532.5 | D13: =D12*182.625*24 -> 120532.5 | E13: =E12*182.625*24 -> 164362.5 | F13: =F12*182.625*24 -> 164362.5 | G13: =G12*182.625*24 -> 197235 | H13: =H12*182.625*24 -> 197235 | I13: =I12*182.625*24 -> 197235 | J13: =J12*182.625*24 -> 197235 | ... AF13: =AF12*182.625*24 -> 197235
A15: RENEWABLE GENERATION + BESS
B16: Gross Solar Generation (MWh) | C16: =Assumptions!$F$20*Assumptions!$F$21*(1-Assumptions!$F$23)*C7*(182.625/365.25) -> 73332 | D16: =Assumptions!$F$20*Assumptions!$F$21*(1-Assumptions!$F$23)*D7*(182.625/365.25) -> 73147.06 | E16: =Assumptions!$F$20*Assumptions!$F$21*(1-Assumptions!$F$23)*E7*(182.625/365.25) -> 72965.59 | F16: =Assumptions!$F$20*Assumptions!$F$21*(1-Assumptions!$F$23)*F7*(182.625/365.25) -> 72781.574 | G16: =Assumptions!$F$20*Assumptions!$F$21*(1-Assumptions!$F$23)*G7*(182.625/365.25) -> 72601.011 | H16: =Assumptions!$F$20*Assumptions!$F$21*(1-Assumptions!$F$23)*H7*(182.625/365.25) -> 72417.915 | I16: =Assumptions!$F$20*Assumptions!$F$21*(1-Assumptions!$F$23)*I7*(182.625/365.25) -> 72238.254 | J16: =Assumptions!$F$20*Assumptions!$F$21*(1-Assumptions!$F$23)*J7*(182.625/365.25) -> 72056.073 | ... AF16: =Assumptions!$F$20*Assumptions!$F$21*(1-Assumptions!$F$23)*AF7*(182.625/365.25) -> 68190.36
B17: BESS Round-Trip Loss (MWh) | C17: =C16*Assumptions!$F$26*(1-Assumptions!$F$25) -> 2199.96 | D17: =D16*Assumptions!$F$26*(1-Assumptions!$F$25) -> 2194.4118 | E17: =E16*Assumptions!$F$26*(1-Assumptions!$F$25) -> 2188.9677 | F17: =F16*Assumptions!$F$26*(1-Assumptions!$F$25) -> 2183.4472 | G17: =G16*Assumptions!$F$26*(1-Assumptions!$F$25) -> 2178.0303 | H17: =H16*Assumptions!$F$26*(1-Assumptions!$F$25) -> 2172.5374 | I17: =I16*Assumptions!$F$26*(1-Assumptions!$F$25) -> 2167.1476 | J17: =J16*Assumptions!$F$26*(1-Assumptions!$F$25) -> 2161.6822 | ... AF17: =AF16*Assumptions!$F$26*(1-Assumptions!$F$25) -> 2045.7108
B18: Net Renewable Supply to DC (MWh) | C18: =C16-C17 -> 71132.04 | D18: =D16-D17 -> 70952.648 | E18: =E16-E17 -> 70776.623 | F18: =F16-F17 -> 70598.127 | G18: =G16-G17 -> 70422.981 | H18: =H16-H17 -> 70245.378 | I18: =I16-I17 -> 70071.107 | J18: =J16-J17 -> 69894.39 | ... AF18: =AF16-AF17 -> 66144.65
B19: Grid Shortfall (MWh) | C19: =MAX(0,C13-C18) -> 49400.46 | D19: =MAX(0,D13-D18) -> 49579.852 | E19: =MAX(0,E13-E18) -> 93585.877 | F19: =MAX(0,F13-F18) -> 93764.373 | G19: =MAX(0,G13-G18) -> 126812.02 | H19: =MAX(0,H13-H18) -> 126989.62 | I19: =MAX(0,I13-I18) -> 127163.89 | J19: =MAX(0,J13-J18) -> 127340.61 | ... AF19: =MAX(0,AF13-AF18) -> 131090.35
B20: Renewable Self-Sufficiency % | C20: =MIN(1,C18/C13) -> 0.59014822 | D20: =MIN(1,D18/D13) -> 0.58865989 | E20: =MIN(1,E18/E13) -> 0.43061296 | F20: =MIN(1,F18/F13) -> 0.42952697 | G20: =MIN(1,G18/G13) -> 0.35705114 | H20: =MIN(1,H18/H13) -> 0.35615067 | I20: =MIN(1,I18/I13) -> 0.3552671 | J20: =MIN(1,J18/J13) -> 0.35437113 | ... AF20: =MIN(1,AF18/AF13) -> 0.33535959
A22: DATA CENTRE REVENUE
B23: Capacity Revenue — Contracted (Take-or-Pay) ($) | C23: =Assumptions!$F$9*1000*Assumptions!$F$16*Assumptions!$F$14*C6*'Timing & Calendar'!C$13 -> 3774000 | D23: =Assumptions!$F$9*1000*Assumptions!$F$16*Assumptions!$F$14*D6*'Timing & Calendar'!D$13 -> 3815600.7 | E23: =Assumptions!$F$9*1000*Assumptions!$F$16*Assumptions!$F$14*E6*'Timing & Calendar'!E$13 -> 3856970.6 | F23: =Assumptions!$F$9*1000*Assumptions!$F$16*Assumptions!$F$14*F6*'Timing & Calendar'!F$13 -> 3899485.9 | G23: =Assumptions!$F$9*1000*Assumptions!$F$16*Assumptions!$F$14*G6*'Timing & Calendar'!G$13 -> 3941765.2 | H23: =Assumptions!$F$9*1000*Assumptions!$F$16*Assumptions!$F$14*H6*'Timing & Calendar'!H$13 -> 3985215.2 | I23: =Assumptions!$F$9*1000*Assumptions!$F$16*Assumptions!$F$14*I6*'Timing & Calendar'!I$13 -> 4028424 | J23: =Assumptions!$F$9*1000*Assumptions!$F$16*Assumptions!$F$14*J6*'Timing & Calendar'!J$13 -> 4072829.3 | ... AF23: =Assumptions!$F$9*1000*Assumptions!$F$16*Assumptions!$F$14*AF6*'Timing & Calendar'!AF$13 -> 5174430.1
B24: Capacity Revenue — Residual (Spot, utilisation-based) ($) | C24: =Assumptions!$F$9*1000*(1-Assumptions!$F$16)*C10*Assumptions!$F$14*C6*'Timing & Calendar'!C$13 -> 366300 | D24: =Assumptions!$F$9*1000*(1-Assumptions!$F$16)*D10*Assumptions!$F$14*D6*'Timing & Calendar'!D$13 -> 370337.72 | E24: =Assumptions!$F$9*1000*(1-Assumptions!$F$16)*E10*Assumptions!$F$14*E6*'Timing & Calendar'!E$13 -> 510481.4 | F24: =Assumptions!$F$9*1000*(1-Assumptions!$F$16)*F10*Assumptions!$F$14*F6*'Timing & Calendar'!F$13 -> 516108.42 | G24: =Assumptions!$F$9*1000*(1-Assumptions!$F$16)*G10*Assumptions!$F$14*G6*'Timing & Calendar'!G$13 -> 626045.06 | H24: =Assumptions!$F$9*1000*(1-Assumptions!$F$16)*H10*Assumptions!$F$14*H6*'Timing & Calendar'!H$13 -> 632945.94 | I24: =Assumptions!$F$9*1000*(1-Assumptions!$F$16)*I10*Assumptions!$F$14*I6*'Timing & Calendar'!I$13 -> 639808.52 | J24: =Assumptions!$F$9*1000*(1-Assumptions!$F$16)*J10*Assumptions!$F$14*J6*'Timing & Calendar'!J$13 -> 646861.12 | ... AF24: =Assumptions!$F$9*1000*(1-Assumptions!$F$16)*AF10*Assumptions!$F$14*AF6*'Timing & Calendar'!AF$13 -> 821821.25
B25: Energy Revenue ($) | C25: =C13*1000*Assumptions!$F$15*C6 -> 18682538 | D25: =D13*1000*Assumptions!$F$15*D6 -> 18888475 | E25: =E13*1000*Assumptions!$F$15*E6 -> 26036276 | F25: =F13*1000*Assumptions!$F$15*F6 -> 26323273 | G25: =G13*1000*Assumptions!$F$15*G6 -> 31930413 | H25: =H13*1000*Assumptions!$F$15*H6 -> 32282381 | I25: =I13*1000*Assumptions!$F$15*I6 -> 32632396 | J25: =J13*1000*Assumptions!$F$15*J6 -> 32992102 | ... AF25: =AF13*1000*Assumptions!$F$15*AF6 -> 41915660
B26: TOTAL DATA CENTRE REVENUE ($) | C26: =C23+C24+C25 -> 22822838 | D26: =D23+D24+D25 -> 23074413 | E26: =E23+E24+E25 -> 30403728 | F26: =F23+F24+F25 -> 30738867 | G26: =G23+G24+G25 -> 36498223 | H26: =H23+H24+H25 -> 36900542 | I26: =I23+I24+I25 -> 37300629 | J26: =J23+J24+J25 -> 37711793 | ... AF26: =AF23+AF24+AF25 -> 47911912
A28: OPERATING COSTS
B29: Data Centre O&M ($) | C29: =Assumptions!$F$34*1000*Assumptions!$F$9/2*C6 -> 3600000 | D29: =Assumptions!$F$34*1000*Assumptions!$F$9/2*D6 -> 3639682.7 | E29: =Assumptions!$F$34*1000*Assumptions!$F$9/2*E6 -> 3679145.2 | F29: =Assumptions!$F$34*1000*Assumptions!$F$9/2*F6 -> 3719700.3 | G29: =Assumptions!$F$34*1000*Assumptions!$F$9/2*G6 -> 3760030.4 | H29: =Assumptions!$F$34*1000*Assumptions!$F$9/2*H6 -> 3801477.1 | I29: =Assumptions!$F$34*1000*Assumptions!$F$9/2*I6 -> 3842693.8 | J29: =Assumptions!$F$34*1000*Assumptions!$F$9/2*J6 -> 3885051.7 | ... AF29: =Assumptions!$F$34*1000*Assumptions!$F$9/2*AF6 -> 4935863.4
B30: Renewable O&M ($) | C30: =Assumptions!$F$35*1000*Assumptions!$F$20/2*C6 -> 810000 | D30: =Assumptions!$F$35*1000*Assumptions!$F$20/2*D6 -> 818928.61 | E30: =Assumptions!$F$35*1000*Assumptions!$F$20/2*E6 -> 827807.67 | F30: =Assumptions!$F$35*1000*Assumptions!$F$20/2*F6 -> 836932.58 | G30: =Assumptions!$F$35*1000*Assumptions!$F$20/2*G6 -> 846006.84 | H30: =Assumptions!$F$35*1000*Assumptions!$F$20/2*H6 -> 855332.35 | I30: =Assumptions!$F$35*1000*Assumptions!$F$20/2*I6 -> 864606.11 | J30: =Assumptions!$F$35*1000*Assumptions!$F$20/2*J6 -> 874136.64 | ... AF30: =Assumptions!$F$35*1000*Assumptions!$F$20/2*AF6 -> 1110569.3
B31: Land Lease & Security ($) | C31: =Assumptions!$F$36*1000/2*C6 -> 175000 | D31: =Assumptions!$F$36*1000/2*D6 -> 176929.02 | E31: =Assumptions!$F$36*1000/2*E6 -> 178847.34 | F31: =Assumptions!$F$36*1000/2*F6 -> 180818.77 | G31: =Assumptions!$F$36*1000/2*G6 -> 182779.25 | H31: =Assumptions!$F$36*1000/2*H6 -> 184794.03 | I31: =Assumptions!$F$36*1000/2*I6 -> 186797.62 | J31: =Assumptions!$F$36*1000/2*J6 -> 188856.68 | ... AF31: =Assumptions!$F$36*1000/2*AF6 -> 239937.8
B32: Grid Backup / Top-Up Cost ($) | C32: =C19*1000*Assumptions!$F$17*C6 -> 6916064.4 | D32: =D19*1000*Assumptions!$F$17*D6 -> 7017691.7 | E32: =E19*1000*Assumptions!$F$17*E6 -> 13390068 | F32: =F19*1000*Assumptions!$F$17*F6 -> 13563487 | G32: =G19*1000*Assumptions!$F$17*G6 -> 18542885 | H32: =H19*1000*Assumptions!$F$17*H6 -> 18773539 | I32: =I19*1000*Assumptions!$F$17*I6 -> 19003130 | J32: =J19*1000*Assumptions!$F$17*J6 -> 19239300 | ... AF32: =AF19*1000*Assumptions!$F$17*AF6 -> 25162825
B33: TOTAL OPERATING COSTS ($) | C33: =C29+C30+C31+C32 -> 11501064 | D33: =D29+D30+D31+D32 -> 11653232 | E33: =E29+E30+E31+E32 -> 18075868 | F33: =F29+F30+F31+F32 -> 18300938 | G33: =G29+G30+G31+G32 -> 23331702 | H33: =H29+H30+H31+H32 -> 23615142 | I33: =I29+I30+I31+I32 -> 23897227 | J33: =J29+J30+J31+J32 -> 24187345 | ... AF33: =AF29+AF30+AF31+AF32 -> 31449195
A35: EBITDA
B36: EBITDA ($) | C36: =C26-C33 -> 11321773 | D36: =D26-D33 -> 11421181 | E36: =E26-E33 -> 12327860 | F36: =F26-F33 -> 12437929 | G36: =G26-G33 -> 13166522 | H36: =H26-H33 -> 13285400 | I36: =I26-I33 -> 13403401 | J36: =J26-J33 -> 13524448 | ... AF36: =AF26-AF33 -> 16462717

Sheet Debt & Financing
B1: DEBT & FINANCING — Tax, CFADS, Sculpted Senior Debt (Target 1.35x Min DSCR, capped at 65% Gearing)
A3: PERIOD REFERENCE & TAX
B4: Period # | C4: ='Timing & Calendar'!C$10 -> 1 | D4: ='Timing & Calendar'!D$10 -> 2 | E4: ='Timing & Calendar'!E$10 -> 3 | F4: ='Timing & Calendar'!F$10 -> 4 | G4: ='Timing & Calendar'!G$10 -> 5 | H4: ='Timing & Calendar'!H$10 -> 6 | I4: ='Timing & Calendar'!I$10 -> 7 | J4: ='Timing & Calendar'!J$10 -> 8 | ... AF4: ='Timing & Calendar'!AF$10 -> 30
B5: EBITDA ($) | C5: =Operations!C36 -> 11321773 | D5: =Operations!D36 -> 11421181 | E5: =Operations!E36 -> 12327860 | F5: =Operations!F36 -> 12437929 | G5: =Operations!G36 -> 13166522 | H5: =Operations!H36 -> 13285400 | I5: =Operations!I36 -> 13403401 | J5: =Operations!J36 -> 13524448 | ... AF5: =Operations!AF36 -> 16462717
B6: Tax Depreciation — Data Centre ($) | C6: =IF(1<=2*Assumptions!$F$50,Construction!$C$4/(2*Assumptions!$F$50),0) -> 17272727 | D6: =IF(2<=2*Assumptions!$F$50,Construction!$C$4/(2*Assumptions!$F$50),0) -> 17272727 | E6: =IF(3<=2*Assumptions!$F$50,Construction!$C$4/(2*Assumptions!$F$50),0) -> 17272727 | F6: =IF(4<=2*Assumptions!$F$50,Construction!$C$4/(2*Assumptions!$F$50),0) -> 17272727 | G6: =IF(5<=2*Assumptions!$F$50,Construction!$C$4/(2*Assumptions!$F$50),0) -> 17272727 | H6: =IF(6<=2*Assumptions!$F$50,Construction!$C$4/(2*Assumptions!$F$50),0) -> 17272727 | I6: =IF(7<=2*Assumptions!$F$50,Construction!$C$4/(2*Assumptions!$F$50),0) -> 17272727 | J6: =IF(8<=2*Assumptions!$F$50,Construction!$C$4/(2*Assumptions!$F$50),0) -> 17272727 | K6: =IF(9<=2*Assumptions!$F$50,Construction!$C$4/(2*Assumptions!$F$50),0) -> 17272727 | L6: =IF(10<=2*Assumptions!$F$50,Construction!$C$4/(2*Assumptions!$F$50),0) -> 17272727 | M6: =IF(11<=2*Assumptions!$F$50,Construction!$C$4/(2*Assumptions!$F$50),0) -> 17272727 | N6: =IF(12<=2*Assumptions!$F$50,Construction!$C$4/(2*Assumptions!$F$50),0) -> 17272727 | O6: =IF(13<=2*Assumptions!$F$50,Construction!$C$4/(2*Assumptions!$F$50),0) -> 17272727 | P6: =IF(14<=2*Assumptions!$F$50,Construction!$C$4/(2*Assumptions!$F$50),0) -> 17272727 | Q6: =IF(15<=2*Assumptions!$F$50,Construction!$C$4/(2*Assumptions!$F$50),0) -> 17272727 | R6: =IF(16<=2*Assumptions!$F$50,Construction!$C$4/(2*Assumptions!$F$50),0) -> 17272727 | S6: =IF(17<=2*Assumptions!$F$50,Construction!$C$4/(2*Assumptions!$F$50),0) -> 17272727 | T6: =IF(18<=2*Assumptions!$F$50,Construction!$C$4/(2*Assumptions!$F$50),0) -> 17272727 | U6: =IF(19<=2*Assumptions!$F$50,Construction!$C$4/(2*Assumptions!$F$50),0) -> 17272727 | V6: =IF(20<=2*Assumptions!$F$50,Construction!$C$4/(2*Assumptions!$F$50),0) -> 17272727 | W6: =IF(21<=2*Assumptions!$F$50,Construction!$C$4/(2*Assumptions!$F$50),0) -> 17272727 | X6: =IF(22<=2*Assumptions!$F$50,Construction!$C$4/(2*Assumptions!$F$50),0) -> 17272727 | Y6: =IF(23<=2*Assumptions!$F$50,Construction!$C$4/(2*Assumptions!$F$50),0) -> 0 | Z6: =IF(24<=2*Assumptions!$F$50,Construction!$C$4/(2*Assumptions!$F$50),0) -> 0 | AA6: =IF(25<=2*Assumptions!$F$50,Construction!$C$4/(2*Assumptions!$F$50),0) -> 0 | AB6: =IF(26<=2*Assumptions!$F$50,Construction!$C$4/(2*Assumptions!$F$50),0) -> 0 | AC6: =IF(27<=2*Assumptions!$F$50,Construction!$C$4/(2*Assumptions!$F$50),0) -> 0 | AD6: =IF(28<=2*Assumptions!$F$50,Construction!$C$4/(2*Assumptions!$F$50),0) -> 0 | AE6: =IF(29<=2*Assumptions!$F$50,Construction!$C$4/(2*Assumptions!$F$50),0) -> 0 | AF6: =IF(30<=2*Assumptions!$F$50,Construction!$C$4/(2*Assumptions!$F$50),0) -> 0
B7: Tax Depreciation — Renewable ($) | C7: =IF(1<=2*Assumptions!$F$51,Construction!$C$5/(2*Assumptions!$F$51),0) -> 4312500 | D7: =IF(2<=2*Assumptions!$F$51,Construction!$C$5/(2*Assumptions!$F$51),0) -> 4312500 | E7: =IF(3<=2*Assumptions!$F$51,Construction!$C$5/(2*Assumptions!$F$51),0) -> 4312500 | F7: =IF(4<=2*Assumptions!$F$51,Construction!$C$5/(2*Assumptions!$F$51),0) -> 4312500 | G7: =IF(5<=2*Assumptions!$F$51,Construction!$C$5/(2*Assumptions!$F$51),0) -> 4312500 | H7: =IF(6<=2*Assumptions!$F$51,Construction!$C$5/(2*Assumptions!$F$51),0) -> 4312500 | I7: =IF(7<=2*Assumptions!$F$51,Construction!$C$5/(2*Assumptions!$F$51),0) -> 4312500 | J7: =IF(8<=2*Assumptions!$F$51,Construction!$C$5/(2*Assumptions!$F$51),0) -> 4312500 | K7: =IF(9<=2*Assumptions!$F$51,Construction!$C$5/(2*Assumptions!$F$51),0) -> 4312500 | L7: =IF(10<=2*Assumptions!$F$51,Construction!$C$5/(2*Assumptions!$F$51),0) -> 4312500 | M7: =IF(11<=2*Assumptions!$F$51,Construction!$C$5/(2*Assumptions!$F$51),0) -> 4312500 | N7: =IF(12<=2*Assumptions!$F$51,Construction!$C$5/(2*Assumptions!$F$51),0) -> 4312500 | O7: =IF(13<=2*Assumptions!$F$51,Construction!$C$5/(2*Assumptions!$F$51),0) -> 4312500 | P7: =IF(14<=2*Assumptions!$F$51,Construction!$C$5/(2*Assumptions!$F$51),0) -> 4312500 | Q7: =IF(15<=2*Assumptions!$F$51,Construction!$C$5/(2*Assumptions!$F$51),0) -> 4312500 | R7: =IF(16<=2*Assumptions!$F$51,Construction!$C$5/(2*Assumptions!$F$51),0) -> 4312500 | S7: =IF(17<=2*Assumptions!$F$51,Construction!$C$5/(2*Assumptions!$F$51),0) -> 4312500 | T7: =IF(18<=2*Assumptions!$F$51,Construction!$C$5/(2*Assumptions!$F$51),0) -> 4312500 | U7: =IF(19<=2*Assumptions!$F$51,Construction!$C$5/(2*Assumptions!$F$51),0) -> 4312500 | V7: =IF(20<=2*Assumptions!$F$51,Construction!$C$5/(2*Assumptions!$F$51),0) -> 4312500 | W7: =IF(21<=2*Assumptions!$F$51,Construction!$C$5/(2*Assumptions!$F$51),0) -> 4312500 | X7: =IF(22<=2*Assumptions!$F$51,Construction!$C$5/(2*Assumptions!$F$51),0) -> 4312500 | Y7: =IF(23<=2*Assumptions!$F$51,Construction!$C$5/(2*Assumptions!$F$51),0) -> 4312500 | Z7: =IF(24<=2*Assumptions!$F$51,Construction!$C$5/(2*Assumptions!$F$51),0) -> 4312500 | AA7: =IF(25<=2*Assumptions!$F$51,Construction!$C$5/(2*Assumptions!$F$51),0) -> 0 | AB7: =IF(26<=2*Assumptions!$F$51,Construction!$C$5/(2*Assumptions!$F$51),0) -> 0 | AC7: =IF(27<=2*Assumptions!$F$51,Construction!$C$5/(2*Assumptions!$F$51),0) -> 0 | AD7: =IF(28<=2*Assumptions!$F$51,Construction!$C$5/(2*Assumptions!$F$51),0) -> 0 | AE7: =IF(29<=2*Assumptions!$F$51,Construction!$C$5/(2*Assumptions!$F$51),0) -> 0 | AF7: =IF(30<=2*Assumptions!$F$51,Construction!$C$5/(2*Assumptions!$F$51),0) -> 0
B8: Taxable Income (EBITDA less Tax Dep.) ($) | C8: =MAX(0,C5-C6-C7) -> 0 | D8: =MAX(0,D5-D6-D7) -> 0 | E8: =MAX(0,E5-E6-E7) -> 0 | F8: =MAX(0,F5-F6-F7) -> 0 | G8: =MAX(0,G5-G6-G7) -> 0 | H8: =MAX(0,H5-H6-H7) -> 0 | I8: =MAX(0,I5-I6-I7) -> 0 | J8: =MAX(0,J5-J6-J7) -> 0 | ... AF8: =MAX(0,AF5-AF6-AF7) -> 16462717
B9: Cash Tax ($) [Circularity breaker: excl. interest deductibility] | C9: =C8*Assumptions!$F$49 -> 0 | D9: =D8*Assumptions!$F$49 -> 0 | E9: =E8*Assumptions!$F$49 -> 0 | F9: =F8*Assumptions!$F$49 -> 0 | G9: =G8*Assumptions!$F$49 -> 0 | H9: =H8*Assumptions!$F$49 -> 0 | I9: =I8*Assumptions!$F$49 -> 0 | J9: =J8*Assumptions!$F$49 -> 0 | ... AF9: =AF8*Assumptions!$F$49 -> 4115679.2
B10: CFADS — Pre-Financing ($) | C10: =C5-C9 -> 11321773 | D10: =D5-D9 -> 11421181 | E10: =E5-E9 -> 12327860 | F10: =F5-F9 -> 12437929 | G10: =G5-G9 -> 13166522 | H10: =H5-H9 -> 13285400 | I10: =I5-I9 -> 13403401 | J10: =J5-J9 -> 13524448 | ... AF10: =AF5-AF9 -> 12347038
A12: DEBT SIZING (non-circular: CFADS is pre-financing, so sculpted capacity is independent of debt)
B13: Semi-Annual Interest Rate | C13: =Assumptions!$F$40/2 -> 0.03875
B14: Target DSCR | C14: =Assumptions!$F$43 -> 1.35
B15: DSCR-Sculpted Debt Capacity ($) [PV of CFADS/TargetDSCR @ interest rate] | C15: =(C10/$C$14)/(1+$C$13)^1+(D10/$C$14)/(1+$C$13)^2+(E10/$C$14)/(1+$C$13)^3+(F10/$C$14)/(1+$C$13)^4+(G10/$C$14)/(1+$C$13)^5+(H10/$C$14)/(1+$C$13)^6+(I10/$C$14)/(1+$C$13)^7+(J10/$C$14)/(1+$C$13)^8+(K10/$C$14)/(1+$C$13)^9+(L10/$C$14)/(1+$C$13)^10+(M10/$C$14)/(1+$C$13)^11+(N10/$C$14)/(1+$C$13)^12+(O10/$C$14)/(1+$C$13)^13+(P10/$C$14)/(1+$C$13)^14+(Q10/$C$14)/(1+$C$13)^15+(R10/$C$14)/(1+$C$13)^16+(S10/$C$14)/(1+$C$13)^17+(T10/$C$14)/(1+$C$13)^18+(U10/$C$14)/(1+$C$13)^19+(V10/$C$14)/(1+$C$13)^20+(W10/$C$14)/(1+$C$13)^21+(X10/$C$14)/(1+$C$13)^22+(Y10/$C$14)/(1+$C$13)^23+(Z10/$C$14)/(1+$C$13)^24+(AA10/$C$14)/(1+$C$13)^25+(AB10/$C$14)/(1+$C$13)^26+(AC10/$C$14)/(1+$C$13)^27+(AD10/$C$14)/(1+$C$13)^28+(AE10/$C$14)/(1+$C$13)^29+(AF10/$C$14)/(1+$C$13)^30 -> 1.7323959e+08
B16: Gearing Cap ($) [65% x Hard Capex] | C16: =Construction!$C$6*Assumptions!$F$44 -> 314275000
B17: FINAL DEBT SIZE ($) [MIN of the two] | C17: =MIN(C15,C16) -> 1.7323959e+08
B18: Binding Constraint | C18: =IF(C15<C16,"DSCR Sculpting","Gearing Cap") -> DSCR Sculpting
B19: Actual Gearing (Debt / Hard Capex) | C19: =C17/Construction!$C$6 -> 0.35830318
A21: SCULPTED AMORTISATION SCHEDULE
B22: Opening Balance ($) | C22: =$C$17 -> 1.7323959e+08 | D22: =C27 -> 1.7156612e+08 | E22: =D27 -> 1.6975418e+08 | F22: =E27 -> 1.672004e+08 | G22: =F27 -> 1.6446614e+08 | H22: =G27 -> 1.6108622e+08 | I22: =H27 -> 1.5748728e+08 | J22: =I27 -> 1.5366146e+08 | K22: =J27 -> 1.4959774e+08 | ... AF22: =AE27 -> 8804768.9
B23: Interest ($) | C23: =C22*$C$13 -> 6713034.1 | D23: =D22*$C$13 -> 6648187.3 | E23: =E22*$C$13 -> 6577974.4 | F23: =F22*$C$13 -> 6479015.7 | G23: =G22*$C$13 -> 6373062.9 | H23: =H22*$C$13 -> 6242091.2 | I23: =I22*$C$13 -> 6102632 | J23: =J22*$C$13 -> 5954381.7 | ... AF23: =AF22*$C$13 -> 341184.8
B24: Target Debt Service (CFADS/TargetDSCR) ($) | C24: =C10/$C$14 -> 8386498.6 | D24: =D10/$C$14 -> 8460134.1 | E24: =E10/$C$14 -> 9131747.9 | F24: =F10/$C$14 -> 9213280.8 | G24: =G10/$C$14 -> 9752979.1 | H24: =H10/$C$14 -> 9841037 | I24: =I10/$C$14 -> 9928445.4 | J24: =J10/$C$14 -> 10018109 | ... AF24: =AF10/$C$14 -> 9145953.7
B25: Scheduled Principal ($) | C25: =MIN(C22,MAX(0,C24-C23)) -> 1673464.5 | D25: =MIN(D22,MAX(0,D24-D23)) -> 1811946.8 | E25: =MIN(E22,MAX(0,E24-E23)) -> 2553773.5 | F25: =MIN(F22,MAX(0,F24-F23)) -> 2734265.2 | G25: =MIN(G22,MAX(0,G24-G23)) -> 3379916.2 | H25: =MIN(H22,MAX(0,H24-H23)) -> 3598945.9 | I25: =MIN(I22,MAX(0,I24-I23)) -> 3825813.5 | J25: =MIN(J22,MAX(0,J24-J23)) -> 4063727.6 | ... AE25: =MIN(AE22,MAX(0,AE24-AE23)) -> 8397296.6 | AF25: =AF22 -> 8804768.9
B26: Total Debt Service ($) | C26: =C23+C25 -> 8386498.6 | D26: =D23+D25 -> 8460134.1 | E26: =E23+E25 -> 9131747.9 | F26: =F23+F25 -> 9213280.8 | G26: =G23+G25 -> 9752979.1 | H26: =H23+H25 -> 9841037 | I26: =I23+I25 -> 9928445.4 | J26: =J23+J25 -> 10018109 | ... AF26: =AF23+AF25 -> 9145953.7
B27: Closing Balance ($) | C27: =C22-C25 -> 1.7156612e+08 | D27: =D22-D25 -> 1.6975418e+08 | E27: =E22-E25 -> 1.672004e+08 | F27: =F22-F25 -> 1.6446614e+08 | G27: =G22-G25 -> 1.6108622e+08 | H27: =H22-H25 -> 1.5748728e+08 | I27: =I22-I25 -> 1.5366146e+08 | J27: =J22-J25 -> 1.4959774e+08 | ... AF27: =AF22-AF25 -> 0
B28: DSCR (CFADS / Debt Service) | C28: =IF(C26=0,"n/a",C10/C26) -> 1.35 | D28: =IF(D26=0,"n/a",D10/D26) -> 1.35 | E28: =IF(E26=0,"n/a",E10/E26) -> 1.35 | F28: =IF(F26=0,"n/a",F10/F26) -> 1.35 | G28: =IF(G26=0,"n/a",G10/G26) -> 1.35 | H28: =IF(H26=0,"n/a",H10/H26) -> 1.35 | I28: =IF(I26=0,"n/a",I10/I26) -> 1.35 | J28: =IF(J26=0,"n/a",J10/J26) -> 1.35 | ... AF28: =IF(AF26=0,"n/a",AF10/AF26) -> 1.35
B31: CHECK: Final Closing Balance = 0 | C31: =IF(ABS(AF27)<1,"OK","ERROR") -> OK
B32: CHECK: Min DSCR >= Target | C32: =IF(MIN(C28:AF28)>=C14-0.001,"OK","ERROR") -> OK
A34: DSRA (6 MONTHS FORWARD DEBT SERVICE)
B35: DSRA Target (next period DS) ($) | C35: =D26*(Assumptions!$F$42/6) -> 8460134.1 | D35: =E26*(Assumptions!$F$42/6) -> 9131747.9 | E35: =F26*(Assumptions!$F$42/6) -> 9213280.8 | F35: =G26*(Assumptions!$F$42/6) -> 9752979.1 | G35: =H26*(Assumptions!$F$42/6) -> 9841037 | H35: =I26*(Assumptions!$F$42/6) -> 9928445.4 | I35: =J26*(Assumptions!$F$42/6) -> 10018109 | J35: =K26*(Assumptions!$F$42/6) -> 10107606 | ... AE35: =AF26*(Assumptions!$F$42/6) -> 9145953.7 | AF35: =0 -> 0
B36: Initial DSRA Funding at COD ($) | C36: =C35 -> 8460134.1

Sheet Cash Flow Waterfall
B1: CASH FLOW WATERFALL — Standard Priority of Payments (30 Semi-Annual Periods)
B3: Period # | C3: ='Timing & Calendar'!C$10 -> 1 | D3: ='Timing & Calendar'!D$10 -> 2 | E3: ='Timing & Calendar'!E$10 -> 3 | F3: ='Timing & Calendar'!F$10 -> 4 | G3: ='Timing & Calendar'!G$10 -> 5 | H3: ='Timing & Calendar'!H$10 -> 6 | I3: ='Timing & Calendar'!I$10 -> 7 | J3: ='Timing & Calendar'!J$10 -> 8 | ... AF3: ='Timing & Calendar'!AF$10 -> 30
A5: 1. OPERATING CASH FLOW
B6: Data Centre Revenue ($) | C6: =Operations!C26 -> 22822838 | D6: =Operations!D26 -> 23074413 | E6: =Operations!E26 -> 30403728 | F6: =Operations!F26 -> 30738867 | G6: =Operations!G26 -> 36498223 | H6: =Operations!H26 -> 36900542 | I6: =Operations!I26 -> 37300629 | J6: =Operations!J26 -> 37711793 | ... AF6: =Operations!AF26 -> 47911912
B7: Less: Operating Costs ($) | C7: =Operations!C33 -> 11501064 | D7: =Operations!D33 -> 11653232 | E7: =Operations!E33 -> 18075868 | F7: =Operations!F33 -> 18300938 | G7: =Operations!G33 -> 23331702 | H7: =Operations!H33 -> 23615142 | I7: =Operations!I33 -> 23897227 | J7: =Operations!J33 -> 24187345 | ... AF7: =Operations!AF33 -> 31449195
B8: EBITDA ($) | C8: =C6-C7 -> 11321773 | D8: =D6-D7 -> 11421181 | E8: =E6-E7 -> 12327860 | F8: =F6-F7 -> 12437929 | G8: =G6-G7 -> 13166522 | H8: =H6-H7 -> 13285400 | I8: =I6-I7 -> 13403401 | J8: =J6-J7 -> 13524448 | ... AF8: =AF6-AF7 -> 16462717
B9: Less: Cash Tax ($) | C9: ='Debt & Financing'!C9 -> 0 | D9: ='Debt & Financing'!D9 -> 0 | E9: ='Debt & Financing'!E9 -> 0 | F9: ='Debt & Financing'!F9 -> 0 | G9: ='Debt & Financing'!G9 -> 0 | H9: ='Debt & Financing'!H9 -> 0 | I9: ='Debt & Financing'!I9 -> 0 | J9: ='Debt & Financing'!J9 -> 0 | ... AF9: ='Debt & Financing'!AF9 -> 4115679.2
B10: CFADS ($) | C10: =C8-C9 -> 11321773 | D10: =D8-D9 -> 11421181 | E10: =E8-E9 -> 12327860 | F10: =F8-F9 -> 12437929 | G10: =G8-G9 -> 13166522 | H10: =H8-H9 -> 13285400 | I10: =I8-I9 -> 13403401 | J10: =J8-J9 -> 13524448 | ... AF10: =AF8-AF9 -> 12347038
A12: 2. SENIOR DEBT SERVICE
B13: Less: Senior Debt Service (Interest + Principal) ($) | C13: ='Debt & Financing'!C26 -> 8386498.6 | D13: ='Debt & Financing'!D26 -> 8460134.1 | E13: ='Debt & Financing'!E26 -> 9131747.9 | F13: ='Debt & Financing'!F26 -> 9213280.8 | G13: ='Debt & Financing'!G26 -> 9752979.1 | H13: ='Debt & Financing'!H26 -> 9841037 | I13: ='Debt & Financing'!I26 -> 9928445.4 | J13: ='Debt & Financing'!J26 -> 10018109 | ... AF13: ='Debt & Financing'!AF26 -> 9145953.7
B14: Cash Flow after Debt Service ($) | C14: =C10-C13 -> 2935274.5 | D14: =D10-D13 -> 2961046.9 | E14: =E10-E13 -> 3196111.8 | F14: =F10-F13 -> 3224648.3 | G14: =G10-G13 -> 3413542.7 | H14: =H10-H13 -> 3444363 | I14: =I10-I13 -> 3474955.9 | J14: =J10-J13 -> 3506338.2 | ... AF14: =AF10-AF13 -> 3201083.8
B15: DSCR (CFADS / Debt Service) | C15: ='Debt & Financing'!C28 -> 1.35 | D15: ='Debt & Financing'!D28 -> 1.35 | E15: ='Debt & Financing'!E28 -> 1.35 | F15: ='Debt & Financing'!F28 -> 1.35 | G15: ='Debt & Financing'!G28 -> 1.35 | H15: ='Debt & Financing'!H28 -> 1.35 | I15: ='Debt & Financing'!I28 -> 1.35 | J15: ='Debt & Financing'!J28 -> 1.35 | ... AF15: ='Debt & Financing'!AF28 -> 1.35
A17: 3. RESERVES
B18: Less: DSRA Funding / Add: DSRA Release ($) | C18: =Reserves!C9 -> 0 | D18: =Reserves!D9 -> 671613.78 | E18: =Reserves!E9 -> 81532.935 | F18: =Reserves!F9 -> 539698.25 | G18: =Reserves!G9 -> 88057.936 | H18: =Reserves!H9 -> 87408.433 | I18: =Reserves!I9 -> 89663.832 | J18: =Reserves!J9 -> 89496.65 | ... AF18: =Reserves!AF9 -> -9145953.7
B19: Less: Augmentation Reserve Contribution ($) | C19: =Reserves!C14 -> 690000 | D19: =Reserves!D14 -> 690000 | E19: =Reserves!E14 -> 690000 | F19: =Reserves!F14 -> 690000 | G19: =Reserves!G14 -> 690000 | H19: =Reserves!H14 -> 690000 | I19: =Reserves!I14 -> 690000 | J19: =Reserves!J14 -> 690000 | ... AF19: =Reserves!AF14 -> 690000
B20: Less: Augmentation Capex Shortfall ($) | C20: =Reserves!C16 -> 0 | D20: =Reserves!D16 -> 0 | E20: =Reserves!E16 -> 0 | F20: =Reserves!F16 -> 0 | G20: =Reserves!G16 -> 0 | H20: =Reserves!H16 -> 0 | I20: =Reserves!I16 -> 0 | J20: =Reserves!J16 -> 0 | ... AF20: =Reserves!AF16 -> 0
A22: 4. DISTRIBUTABLE CASH FLOW
B23: Cash Available for Distribution ($) | C23: =MAX(0,C14-C18-C19-C20) -> 2245274.5 | D23: =MAX(0,D14-D18-D19-D20) -> 1599433.2 | E23: =MAX(0,E14-E18-E19-E20) -> 2424578.8 | F23: =MAX(0,F14-F18-F19-F20) -> 1994950 | G23: =MAX(0,G14-G18-G19-G20) -> 2635484.7 | H23: =MAX(0,H14-H18-H19-H20) -> 2666954.5 | I23: =MAX(0,I14-I18-I19-I20) -> 2695292.1 | J23: =MAX(0,J14-J18-J19-J20) -> 2726841.6 | ... AF23: =MAX(0,AF14-AF18-AF19-AF20) -> 11657038
B24: Equity Distribution ($) | C24: =C23 -> 2245274.5 | D24: =D23 -> 1599433.2 | E24: =E23 -> 2424578.8 | F24: =F23 -> 1994950 | G24: =G23 -> 2635484.7 | H24: =H23 -> 2666954.5 | I24: =I23 -> 2695292.1 | J24: =J23 -> 2726841.6 | ... AF24: =AF23 -> 11657038
B25: CHECK: No Negative Cash Anywhere | C25: =IF(MIN(C23:AF23)>=0,"OK","ERROR") -> OK

Sheet Reserves
B1: RESERVES — DSRA (6 Months Forward Debt Service) & BESS Augmentation Reserve
A3: PERIOD REFERENCE
B4: Period # | C4: ='Timing & Calendar'!C$10 -> 1 | D4: ='Timing & Calendar'!D$10 -> 2 | E4: ='Timing & Calendar'!E$10 -> 3 | F4: ='Timing & Calendar'!F$10 -> 4 | G4: ='Timing & Calendar'!G$10 -> 5 | H4: ='Timing & Calendar'!H$10 -> 6 | I4: ='Timing & Calendar'!I$10 -> 7 | J4: ='Timing & Calendar'!J$10 -> 8 | ... AF4: ='Timing & Calendar'!AF$10 -> 30
A6: DEBT SERVICE RESERVE ACCOUNT (DSRA)
B7: DSRA Opening Balance ($) | C7: ='Debt & Financing'!$C$36 -> 8460134.1 | D7: =C10 -> 8460134.1 | E7: =D10 -> 9131747.9 | F7: =E10 -> 9213280.8 | G7: =F10 -> 9752979.1 | H7: =G10 -> 9841037 | I7: =H10 -> 9928445.4 | J7: =I10 -> 10018109 | K7: =J10 -> 10107606 | ... AF7: =AE10 -> 9145953.7
B8: DSRA Target Balance ($) | C8: ='Debt & Financing'!C35 -> 8460134.1 | D8: ='Debt & Financing'!D35 -> 9131747.9 | E8: ='Debt & Financing'!E35 -> 9213280.8 | F8: ='Debt & Financing'!F35 -> 9752979.1 | G8: ='Debt & Financing'!G35 -> 9841037 | H8: ='Debt & Financing'!H35 -> 9928445.4 | I8: ='Debt & Financing'!I35 -> 10018109 | J8: ='Debt & Financing'!J35 -> 10107606 | ... AF8: ='Debt & Financing'!AF35 -> 0
B9: DSRA Funding / (Release) ($) | C9: =C8-C7 -> 0 | D9: =D8-D7 -> 671613.78 | E9: =E8-E7 -> 81532.935 | F9: =F8-F7 -> 539698.25 | G9: =G8-G7 -> 88057.936 | H9: =H8-H7 -> 87408.433 | I9: =I8-I7 -> 89663.832 | J9: =J8-J7 -> 89496.65 | ... AF9: =AF8-AF7 -> -9145953.7
B10: DSRA Closing Balance ($) | C10: =C7+C9 -> 8460134.1 | D10: =D7+D9 -> 9131747.9 | E10: =E7+E9 -> 9213280.8 | F10: =F7+F9 -> 9752979.1 | G10: =G7+G9 -> 9841037 | H10: =H7+H9 -> 9928445.4 | I10: =I7+I9 -> 10018109 | J10: =J7+J9 -> 10107606 | ... AF10: =AF7+AF9 -> 0
A12: BESS AUGMENTATION RESERVE (mid-life augmentation event)
B13: Augmentation Reserve Opening ($) | C13: =0 -> 0 | D13: =C17 -> 690000 | E13: =D17 -> 1380000 | F13: =E17 -> 2070000 | G13: =F17 -> 2760000 | H13: =G17 -> 3450000 | I13: =H17 -> 4140000 | J13: =I17 -> 4830000 | K13: =J17 -> 5520000 | ... AF13: =AE17 -> 8970000
B14: Periodic Contribution ($) | C14: =Construction!$C$5*Assumptions!$F$28/(Assumptions!$F$27*2) -> 690000 | D14: =Construction!$C$5*Assumptions!$F$28/(Assumptions!$F$27*2) -> 690000 | E14: =Construction!$C$5*Assumptions!$F$28/(Assumptions!$F$27*2) -> 690000 | F14: =Construction!$C$5*Assumptions!$F$28/(Assumptions!$F$27*2) -> 690000 | G14: =Construction!$C$5*Assumptions!$F$28/(Assumptions!$F$27*2) -> 690000 | H14: =Construction!$C$5*Assumptions!$F$28/(Assumptions!$F$27*2) -> 690000 | I14: =Construction!$C$5*Assumptions!$F$28/(Assumptions!$F$27*2) -> 690000 | J14: =Construction!$C$5*Assumptions!$F$28/(Assumptions!$F$27*2) -> 690000 | ... AF14: =Construction!$C$5*Assumptions!$F$28/(Assumptions!$F$27*2) -> 690000
B15: Augmentation Capex Drawn ($) [one-off, target period] | C15: =IF(1=Assumptions!$F$29,MIN(C13+C14,Construction!$C$5*Assumptions!$F$28),0) -> 0 | D15: =IF(2=Assumptions!$F$29,MIN(D13+D14,Construction!$C$5*Assumptions!$F$28),0) -> 0 | E15: =IF(3=Assumptions!$F$29,MIN(E13+E14,Construction!$C$5*Assumptions!$F$28),0) -> 0 | F15: =IF(4=Assumptions!$F$29,MIN(F13+F14,Construction!$C$5*Assumptions!$F$28),0) -> 0 | G15: =IF(5=Assumptions!$F$29,MIN(G13+G14,Construction!$C$5*Assumptions!$F$28),0) -> 0 | H15: =IF(6=Assumptions!$F$29,MIN(H13+H14,Construction!$C$5*Assumptions!$F$28),0) -> 0 | I15: =IF(7=Assumptions!$F$29,MIN(I13+I14,Construction!$C$5*Assumptions!$F$28),0) -> 0 | J15: =IF(8=Assumptions!$F$29,MIN(J13+J14,Construction!$C$5*Assumptions!$F$28),0) -> 0 | K15: =IF(9=Assumptions!$F$29,MIN(K13+K14,Construction!$C$5*Assumptions!$F$28),0) -> 0 | L15: =IF(10=Assumptions!$F$29,MIN(L13+L14,Construction!$C$5*Assumptions!$F$28),0) -> 0 | M15: =IF(11=Assumptions!$F$29,MIN(M13+M14,Construction!$C$5*Assumptions!$F$28),0) -> 0 | N15: =IF(12=Assumptions!$F$29,MIN(N13+N14,Construction!$C$5*Assumptions!$F$28),0) -> 0 | O15: =IF(13=Assumptions!$F$29,MIN(O13+O14,Construction!$C$5*Assumptions!$F$28),0) -> 0 | P15: =IF(14=Assumptions!$F$29,MIN(P13+P14,Construction!$C$5*Assumptions!$F$28),0) -> 0 | Q15: =IF(15=Assumptions!$F$29,MIN(Q13+Q14,Construction!$C$5*Assumptions!$F$28),0) -> 0 | R15: =IF(16=Assumptions!$F$29,MIN(R13+R14,Construction!$C$5*Assumptions!$F$28),0) -> 11040000 | S15: =IF(17=Assumptions!$F$29,MIN(S13+S14,Construction!$C$5*Assumptions!$F$28),0) -> 0 | T15: =IF(18=Assumptions!$F$29,MIN(T13+T14,Construction!$C$5*Assumptions!$F$28),0) -> 0 | U15: =IF(19=Assumptions!$F$29,MIN(U13+U14,Construction!$C$5*Assumptions!$F$28),0) -> 0 | V15: =IF(20=Assumptions!$F$29,MIN(V13+V14,Construction!$C$5*Assumptions!$F$28),0) -> 0 | W15: =IF(21=Assumptions!$F$29,MIN(W13+W14,Construction!$C$5*Assumptions!$F$28),0) -> 0 | X15: =IF(22=Assumptions!$F$29,MIN(X13+X14,Construction!$C$5*Assumptions!$F$28),0) -> 0 | Y15: =IF(23=Assumptions!$F$29,MIN(Y13+Y14,Construction!$C$5*Assumptions!$F$28),0) -> 0 | Z15: =IF(24=Assumptions!$F$29,MIN(Z13+Z14,Construction!$C$5*Assumptions!$F$28),0) -> 0 | AA15: =IF(25=Assumptions!$F$29,MIN(AA13+AA14,Construction!$C$5*Assumptions!$F$28),0) -> 0 | AB15: =IF(26=Assumptions!$F$29,MIN(AB13+AB14,Construction!$C$5*Assumptions!$F$28),0) -> 0 | AC15: =IF(27=Assumptions!$F$29,MIN(AC13+AC14,Construction!$C$5*Assumptions!$F$28),0) -> 0 | AD15: =IF(28=Assumptions!$F$29,MIN(AD13+AD14,Construction!$C$5*Assumptions!$F$28),0) -> 0 | AE15: =IF(29=Assumptions!$F$29,MIN(AE13+AE14,Construction!$C$5*Assumptions!$F$28),0) -> 0 | AF15: =IF(30=Assumptions!$F$29,MIN(AF13+AF14,Construction!$C$5*Assumptions!$F$28),0) -> 0
B16: Augmentation Shortfall (funded from distributable cash) ($) | C16: =IF(1=Assumptions!$F$29,MAX(0,Construction!$C$5*Assumptions!$F$28-(C13+C14)),0) -> 0 | D16: =IF(2=Assumptions!$F$29,MAX(0,Construction!$C$5*Assumptions!$F$28-(D13+D14)),0) -> 0 | E16: =IF(3=Assumptions!$F$29,MAX(0,Construction!$C$5*Assumptions!$F$28-(E13+E14)),0) -> 0 | F16: =IF(4=Assumptions!$F$29,MAX(0,Construction!$C$5*Assumptions!$F$28-(F13+F14)),0) -> 0 | G16: =IF(5=Assumptions!$F$29,MAX(0,Construction!$C$5*Assumptions!$F$28-(G13+G14)),0) -> 0 | H16: =IF(6=Assumptions!$F$29,MAX(0,Construction!$C$5*Assumptions!$F$28-(H13+H14)),0) -> 0 | I16: =IF(7=Assumptions!$F$29,MAX(0,Construction!$C$5*Assumptions!$F$28-(I13+I14)),0) -> 0 | J16: =IF(8=Assumptions!$F$29,MAX(0,Construction!$C$5*Assumptions!$F$28-(J13+J14)),0) -> 0 | K16: =IF(9=Assumptions!$F$29,MAX(0,Construction!$C$5*Assumptions!$F$28-(K13+K14)),0) -> 0 | L16: =IF(10=Assumptions!$F$29,MAX(0,Construction!$C$5*Assumptions!$F$28-(L13+L14)),0) -> 0 | M16: =IF(11=Assumptions!$F$29,MAX(0,Construction!$C$5*Assumptions!$F$28-(M13+M14)),0) -> 0 | N16: =IF(12=Assumptions!$F$29,MAX(0,Construction!$C$5*Assumptions!$F$28-(N13+N14)),0) -> 0 | O16: =IF(13=Assumptions!$F$29,MAX(0,Construction!$C$5*Assumptions!$F$28-(O13+O14)),0) -> 0 | P16: =IF(14=Assumptions!$F$29,MAX(0,Construction!$C$5*Assumptions!$F$28-(P13+P14)),0) -> 0 | Q16: =IF(15=Assumptions!$F$29,MAX(0,Construction!$C$5*Assumptions!$F$28-(Q13+Q14)),0) -> 0 | R16: =IF(16=Assumptions!$F$29,MAX(0,Construction!$C$5*Assumptions!$F$28-(R13+R14)),0) -> 9660000 | S16: =IF(17=Assumptions!$F$29,MAX(0,Construction!$C$5*Assumptions!$F$28-(S13+S14)),0) -> 0 | T16: =IF(18=Assumptions!$F$29,MAX(0,Construction!$C$5*Assumptions!$F$28-(T13+T14)),0) -> 0 | U16: =IF(19=Assumptions!$F$29,MAX(0,Construction!$C$5*Assumptions!$F$28-(U13+U14)),0) -> 0 | V16: =IF(20=Assumptions!$F$29,MAX(0,Construction!$C$5*Assumptions!$F$28-(V13+V14)),0) -> 0 | W16: =IF(21=Assumptions!$F$29,MAX(0,Construction!$C$5*Assumptions!$F$28-(W13+W14)),0) -> 0 | X16: =IF(22=Assumptions!$F$29,MAX(0,Construction!$C$5*Assumptions!$F$28-(X13+X14)),0) -> 0 | Y16: =IF(23=Assumptions!$F$29,MAX(0,Construction!$C$5*Assumptions!$F$28-(Y13+Y14)),0) -> 0 | Z16: =IF(24=Assumptions!$F$29,MAX(0,Construction!$C$5*Assumptions!$F$28-(Z13+Z14)),0) -> 0 | AA16: =IF(25=Assumptions!$F$29,MAX(0,Construction!$C$5*Assumptions!$F$28-(AA13+AA14)),0) -> 0 | AB16: =IF(26=Assumptions!$F$29,MAX(0,Construction!$C$5*Assumptions!$F$28-(AB13+AB14)),0) -> 0 | AC16: =IF(27=Assumptions!$F$29,MAX(0,Construction!$C$5*Assumptions!$F$28-(AC13+AC14)),0) -> 0 | AD16: =IF(28=Assumptions!$F$29,MAX(0,Construction!$C$5*Assumptions!$F$28-(AD13+AD14)),0) -> 0 | AE16: =IF(29=Assumptions!$F$29,MAX(0,Construction!$C$5*Assumptions!$F$28-(AE13+AE14)),0) -> 0 | AF16: =IF(30=Assumptions!$F$29,MAX(0,Construction!$C$5*Assumptions!$F$28-(AF13+AF14)),0) -> 0
B17: Augmentation Reserve Closing ($) | C17: =C13+C14-C15 -> 690000 | D17: =D13+D14-D15 -> 1380000 | E17: =E13+E14-E15 -> 2070000 | F17: =F13+F14-F15 -> 2760000 | G17: =G13+G14-G15 -> 3450000 | H17: =H13+H14-H15 -> 4140000 | I17: =I13+I14-I15 -> 4830000 | J17: =J13+J14-J15 -> 5520000 | ... AF17: =AF13+AF14-AF15 -> 9660000

Sheet Outputs & Dashboard
B1: OUTPUTS & DASHBOARD — Equity Returns and Key Credit Metrics
B2: =CONCATENATE("Active Scenario: ",Cover!$B$7) -> Active Scenario: Base Case
A4: HEADLINE METRICS (feed Cover tiles — do not move these rows)
B5: Equity IRR | C5: =IFERROR(XIRR(EqCF_range,EqDate_range),"n/a") -> -0.11516319
B6: Equity NPV @ Discount Rate ($) | C6: =IFERROR(XNPV($A$52,EqCF_range,EqDate_range),"n/a") -> -2.6884206e+08
B7: Equity Multiple (x) | C7: =SUM(EqCF_pos_range)/ -SUM(EqCF_neg_range) -> 0.26550096
B8: Minimum DSCR (x) | C8: =MIN('Debt & Financing'!C28:AF28) -> 1.35
B9: Average DSCR (x) | C9: =AVERAGE('Debt & Financing'!C28:AF28) -> 1.35
B10: Actual Gearing (%) | C10: ='Debt & Financing'!C19 -> 0.35830318
B11: Total Project Cost ($) | C11: =Construction!C31 -> 5.0785848e+08
B12: COD | C12: =Assumptions!F56 -> 46935
A14: EQUITY CASH FLOW (Construction monthly outflows -> Operating semi-annual distributions)
B15: Date | C15: ='Timing & Calendar'!C$5 -> 46204 | D15: ='Timing & Calendar'!D$5 -> 46235 | E15: ='Timing & Calendar'!E$5 -> 46266 | F15: ='Timing & Calendar'!F$5 -> 46296 | G15: ='Timing & Calendar'!G$5 -> 46327 | H15: ='Timing & Calendar'!H$5 -> 46357 | I15: ='Timing & Calendar'!I$5 -> 46388 | J15: ='Timing & Calendar'!J$5 -> 46419 | ... Z15: ='Timing & Calendar'!Z$5 -> 46905 | AA15: ='Timing & Calendar'!C$12 -> 47118 | AB15: ='Timing & Calendar'!D$12 -> 47299 | AC15: ='Timing & Calendar'!E$12 -> 47483 | AD15: ='Timing & Calendar'!F$12 -> 47664 | AE15: ='Timing & Calendar'!G$12 -> 47848 | AF15: ='Timing & Calendar'!H$12 -> 48029 | AG15: ='Timing & Calendar'!I$12 -> 48213 | AH15: ='Timing & Calendar'!J$12 -> 48395 | ... BD15: ='Timing & Calendar'!AF$12 -> 52412
B16: Equity Cash Flow ($) | C16: =-Construction!C22 -> -2863942.3 | D16: =-Construction!D22 -> -5499550.4 | E16: =-Construction!E22 -> -7905963.8 | F16: =-Construction!F22 -> -10082322 | G16: =-Construction!G22 -> -12027764 | H16: =-Construction!H22 -> -13741429 | I16: =-Construction!I22 -> -15222457 | J16: =-Construction!J22 -> -16469987 | ... Y16: =-Construction!Y22 -> -6577939.1 | Z16: =-(Construction!Z22+Construction!$C$29+Construction!$C$30) -> -15464280 | AA16: ='Cash Flow Waterfall'!C24 -> 2245274.5 | AB16: ='Cash Flow Waterfall'!D24 -> 1599433.2 | AC16: ='Cash Flow Waterfall'!E24 -> 2424578.8 | AD16: ='Cash Flow Waterfall'!F24 -> 1994950 | AE16: ='Cash Flow Waterfall'!G24 -> 2635484.7 | AF16: ='Cash Flow Waterfall'!H24 -> 2666954.5 | AG16: ='Cash Flow Waterfall'!I24 -> 2695292.1 | AH16: ='Cash Flow Waterfall'!J24 -> 2726841.6 | ... BD16: ='Cash Flow Waterfall'!AF24 -> 11657038
A51: Equity Discount Rate (link)
A52: =Assumptions!$F$52 -> 0.12

Sheet Sensitivities & Scenarios
B1: SENSITIVITIES & SCENARIOS
A3: SCENARIO COMPARISON (live — set Cover!B7 to each case and this table updates)
