Workbook

Sheet Cover
B2: Tema Cocoa Processing Plant — Project Finance Model
B5: 15,000 MT/yr installed capacity cocoa grinding facility — Tema, Ghana
B6: Export offtake (contracted + spot, with price floor & take-or-pay) | Senior + mezzanine debt sculpted to min. 1.30x DSCR | Working capital revolver, DSRA & MRA | USD reporting currency
B8: Live Scenario Switcher
B9: Active Scenario (select): | C9: Base | D9: << This single cell drives the entire model (Assumptions, Operations, Debt, Outputs).
B11: Scenario key changes vs Base:
B12: Best: Utilisation +10pts | ICE price +15% | Bean cost -5% | Capex -8% | Interest -0.75% | GHS stable
B13: Worst: Utilisation -15pts | ICE price -20% | Bean cost +15% | Capex +10% | Interest +1.5% | GHS depreciates sharply
B15: Key Outputs Snapshot (active scenario, linked live from Outputs sheet)
B16: Senior Debt at COD ($) | D16: =Outputs!$D$7 -> 1.2653082e+08
B17: Equity at COD ($) | D17: =Outputs!$D$8 -> 67287488
B18: Gearing achieved (%) | D18: =Outputs!$D$9 -> 0.76560595
B19: Equity IRR (%) | D19: =Outputs!$D$13 -> 0
B20: Equity NPV @ discount rate ($) | D20: =Outputs!$D$14 -> -59862784
B21: Equity Multiple (x) | D21: =Outputs!$D$15 -> 0
B22: Minimum DSCR (x) | D22: =Outputs!$D$20 -> -0.10661364
B23: Average DSCR (x) | D23: =Outputs!$D$22 -> 1.0009806
B25: Colour Legend
B26: Amber font / amber fill | D26: Editable input — change here to flex the model
B27: Black font, white fill | D27: Formula calculated within the same sheet
B28: Green font | D28: Link pulled from another sheet
B29: Teal bold font | D29: Key output / positive result
B30: Brown font, amber-warn fill | D30: Check / warning flag — review before signing off
B33: Model built: monthly construction cash-flow, semi-annual operating periods over the 10-year debt tenor.
B34: See 'Audit' sheet for lender-style quality-control checks and 'Glossary' for term definitions.
B37: Table of Content
B38: Assumptions
B39: Timing
B40: Construction
B41: Operations
B42: Waterfall
B43: WorkingCap
B44: Reserves
B45: Outputs
B46: Sensitivities
... B49: Charts

Sheet Assumptions
B2: Assumptions — Base / Best / Worst Case Inputs
B4: Active Scenario: | D4: =Cover!$C$9 -> Base | E4: <<<< Cover | F4: (All 'Active' values below flex automatically with the Cover-sheet switch)
B6: Assumption | C6: Base Case | D6: Best Case | E6: Worst Case | F6: Active | G6: Unit | H6: Notes / Source
B8: 1. Processing Plant & Capacity
B9: Installed capacity | C9: 15000 | D9: 15000 | E9: 15000 | F9: =IF($D$4="Base",C9,IF($D$4="Best",D9,E9)) -> 15000 | G9: MT beans/yr | H9: Fixed nameplate capacity of the Tema grinding plant (not scenario-flexed).
B10: Utilisation — Year 1 | C10: 0.6 | D10: 0.7 | E10: 0.45 | F10: =IF($D$4="Base",C10,IF($D$4="Best",D10,E10)) -> 0.6 | G10: % of capacity | H10: Ramp-up year. Best/Worst flex Base by +/-10 to 15 pts per brief.
B11: Utilisation — Year 2 | C11: 0.8 | D11: 0.9 | E11: 0.65 | F11: =IF($D$4="Base",C11,IF($D$4="Best",D11,E11)) -> 0.8 | G11: % of capacity | H11: Second ramp-up year.
B12: Utilisation — Year 3 onward | C12: 0.95 | D12: 0.98 | E12: 0.8 | F12: =IF($D$4="Base",C12,IF($D$4="Best",D12,E12)) -> 0.95 | G12: % of capacity | H12: Steady-state utilisation for remainder of debt tenor.
B13: Conversion yield (product/bean) | C13: 0.85 | D13: 0.85 | E13: 0.85 | F13: =IF($D$4="Base",C13,IF($D$4="Best",D13,E13)) -> 0.85 | G13: % by weight | H13: User-specified: ~85% of bean input weight converts to saleable product; balance is shell/moisture loss.
B14: Bean-to-product ratio | C14: 1.1764706 | D14: 1.1764706 | E14: 1.1764706 | F14: =IF($D$4="Base",C14,IF($D$4="Best",D14,E14)) -> 1.1764706 | G14: MT bean / MT product | H14: User-specified feedstock intensity (~1/0.85 consistent with 85% yield).
B15: Product mix — Cocoa liquor | C15: 0.4 | D15: 0.4 | E15: 0.4 | F15: =IF($D$4="Base",C15,IF($D$4="Best",D15,E15)) -> 0.4 | G15: % of output | H15: Fixed product slate (not scenario-flexed).
B16: Product mix — Cocoa butter | C16: 0.3 | D16: 0.3 | E16: 0.3 | F16: =IF($D$4="Base",C16,IF($D$4="Best",D16,E16)) -> 0.3 | G16: % of output
B17: Product mix — Cocoa cake/powder | C17: 0.3 | D17: 0.3 | E17: 0.3 | F17: =IF($D$4="Base",C17,IF($D$4="Best",D17,E17)) -> 0.3 | G17: % of output
B19: 2. Product Pricing (USD, ICE Cocoa Benchmark-Linked)
B20: ICE cocoa benchmark price (base, at COD) | C20: 7000 | D20: 8050 | E20: 5600 | F20: =IF($D$4="Base",C20,IF($D$4="Best",D20,E20)) -> 7000 | G20: $/MT | H20: Illustrative base ICE No.2 cocoa futures reference; Best +15%, Worst -20% per brief.
B21: Processing differential — Liquor | C21: 400 | D21: 400 | E21: 400 | F21: =IF($D$4="Base",C21,IF($D$4="Best",D21,E21)) -> 400 | G21: $/MT | H21: Fixed contractual premium/discount to ICE benchmark (editable).
B22: Processing differential — Butter | C22: 1800 | D22: 1800 | E22: 1800 | F22: =IF($D$4="Base",C22,IF($D$4="Best",D22,E22)) -> 1800 | G22: $/MT | H22: Cocoa butter typically trades at the largest premium to bean-equivalent.
B23: Processing differential — Cake/Powder | C23: -300 | D23: -300 | E23: -300 | F23: =IF($D$4="Base",C23,IF($D$4="Best",D23,E23)) -> -300 | G23: $/MT | H23: Cake/powder typically trades at a discount to bean-equivalent.
B24: Contracted (offtake) share of output | C24: 0.8 | D24: 0.8 | E24: 0.8 | F24: =IF($D$4="Base",C24,IF($D$4="Best",D24,E24)) -> 0.8 | G24: % of output | H24: Multi-year offtake agreements with confectionery manufacturers.
B25: Spot export share of output | C25: 0.2 | D25: 0.2 | E25: 0.2 | F25: =IF($D$4="Base",C25,IF($D$4="Best",D25,E25)) -> 0.2 | G25: % of output | H25: Residual volume sold on the spot export market.
B26: Spot differential pass-through factor | C26: 0.5 | D26: 0.5 | E26: 0.5 | F26: =IF($D$4="Base",C26,IF($D$4="Best",D26,E26)) -> 0.5 | G26: % of contract diff. | H26: Spot sales capture only part of the fixed processing differential, reflecting greater ICE-price pass-through/volatility on uncontracted volume.
B28: 3. Bean Procurement (GHS) & FX
B29: COCOBOD producer price (base year) | C29: 3000 | D29: 2850 | E29: 3450 | F29: =IF($D$4="Base",C29,IF($D$4="Best",D29,E29)) -> 3000 | G29: GHS/64kg bag | H29: Best -5%, Worst +15% vs Base per brief.
B30: Producer price annual escalation | C30: 0.12 | D30: 0.06 | E30: 0.18 | F30: =IF($D$4="Base",C30,IF($D$4="Best",D30,E30)) -> 0.12 | G30: % p.a. (GHS nominal) | H30: Nominal GHS escalation is linked to the FX scenario: Best case (stable GHS) assumes materially lower domestic cost inflation (~6%/yr); Worst case (sharp depreciation) assumes higher pass-through domestic inflation (~18%/yr); Base sits at the historical COCOBOD trend (~12%/yr with ~8%/yr GHS depreciation). This reflects the real-world link between a currency's stability and the domestic nominal price inflation it experiences (purchasing-power-parity intuition) -- without this link, a stable-FX Best Case can perversely show weaker USD economics than Base over a 10-year tenor, since nominal GHS cost growth then has no offsetting depreciation benefit.
B31: Bag weight | C31: 64 | D31: 64 | E31: 64 | F31: =IF($D$4="Base",C31,IF($D$4="Best",D31,E31)) -> 64 | G31: kg/bag | H31: Standard COCOBOD bag size.
B32: USD/GHS exchange rate at COD | C32: 13 | D32: 11 | E32: 15 | F32: =IF($D$4="Base",C32,IF($D$4="Best",D32,E32)) -> 13 | G32: GHS per USD | H32: Spot FX at financial close; fixed starting point across scenarios.
B33: Annual GHS depreciation vs USD | C33: 0.05 | D33: 0.01 | E33: 0.1 | F33: =IF($D$4="Base",C33,IF($D$4="Best",D33,E33)) -> 0.05 | G33: % p.a. | H33: Central FX risk driver. Best: GHS holds stable. Worst: sharp depreciation.
B35: 4. Operating Costs (USD)
B36: Plant all-in capex | C36: 12000 | D36: 11040 | E36: 13200 | F36: =IF($D$4="Base",C36,IF($D$4="Best",D36,E36)) -> 12000 | G36: $/MT installed | H36: NOTE ON THIS INPUT: the brief specified $180,000/MT (=$2.7bn total capex for 15,000 MT/yr), which is 1-2 orders of magnitude above observed capex intensity for integrated cocoa liquor/butter/powder plants (industry benchmarks cluster around $3,000-12,000/MT depending on scope and sophistication). At $180,000/MT the resulting debt quantum makes debt service uncoverable by plant cash flow at any realistic price, independent of the O&M assumption. We have used $12,000/MT (~$180m total capex, consistent with the digits in the brief but expressed per the correct order of magnitude) as the working Base Case. This cell is a live amber input -- set it back to 180,000 to reproduce the as-specified stress case.
B37: Annual O&M | C37: 950 | D37: 950 | E37: 950 | F37: =IF($D$4="Base",C37,IF($D$4="Best",D37,E37)) -> 950 | G37: $/MT processed | H37: NOTE ON THIS INPUT: the brief specified $9,500/MT. At that level, O&M alone (~$11,200/MT of product after the 1.18x bean ratio) exceeds achievable product revenue at any realistic ICE cocoa price (recent range ~$3,100-$12,900/MT; 2026 forward curve ~$6,000-6,300/MT), making the plant structurally loss-making and DSCR/IRR undefined regardless of financing structure. This is far above observed cocoa-grinding O&M benchmarks (~$200-500/MT). We have used $950/MT (1/10th of the brief figure) as the working Base Case so the model produces a functioning, bankable result. This cell is a live amber input -- set it back to 9,500 to reproduce the as-specified stress case and observe the resulting covenant breach flagged on the Audit sheet.
B38: Logistics / freight to port & export shipping | C38: 45 | D38: 45 | E38: 45 | F38: =IF($D$4="Base",C38,IF($D$4="Best",D38,E38)) -> 45 | G38: $/MT product | H38: Escalated at USD inflation.
B40: 5. Financing
B41: Debt tenor | C41: 10 | D41: 10 | E41: 10 | F41: =IF($D$4="Base",C41,IF($D$4="Best",D41,E41)) -> 10 | G41: years from COD | H41: Fixed across scenarios.
B42: All-in senior interest rate | C42: 0.095 | D42: 0.0875 | E42: 0.11 | F42: =IF($D$4="Base",C42,IF($D$4="Best",D42,E42)) -> 0.095 | G42: % p.a. | H42: Best -0.75pt, Worst +1.50pt vs Base per brief.
B43: Upfront arrangement fee | C43: 0.015 | D43: 0.015 | E43: 0.015 | F43: =IF($D$4="Base",C43,IF($D$4="Best",D43,E43)) -> 0.015 | G43: % of facility | H43: Charged on committed senior facility; capitalised into debt at COD.
B44: DSRA sizing | C44: 6 | D44: 6 | E44: 6 | F44: =IF($D$4="Base",C44,IF($D$4="Best",D44,E44)) -> 6 | G44: months of debt service | H44: Debt Service Reserve funded at COD, equal to next 6 months (1 semi-annual period) of debt service.
B45: Target minimum DSCR | C45: 1.3 | D45: 1.3 | E45: 1.3 | F45: =IF($D$4="Base",C45,IF($D$4="Best",D45,E45)) -> 1.3 | G45: x | H45: Senior debt sculpted so scheduled debt service never exceeds CFADS / 1.30x.
B46: Target gearing | C46: 0.6 | D46: 0.6 | E46: 0.6 | F46: =IF($D$4="Base",C46,IF($D$4="Best",D46,E46)) -> 0.6 | G46: % debt / total base capex | H46: Senior debt sized at 60% of base plant capex; IDC & fees capitalised on top.
B48: 6. Macro & Tax
B49: USD inflation | C49: 0.022 | D49: 0.022 | E49: 0.022 | F49: =IF($D$4="Base",C49,IF($D$4="Best",D49,E49)) -> 0.022 | G49: % p.a. | H49: Applied to USD-denominated costs and to nominal escalation of ICE price.
...

Sheet Timing
B2: Timing & Calendar
B4: Monthly construction programme and semi-annual operating periods, driven off Assumptions dates.
B6: Construction Programme (Month 1 - 18)
B7: Month # | C7: Month Start | D7: Month End | E7: Cum. Months
B8: 1 | C8: =Assumptions!$F$57 -> 46388 | D8: =EDATE(C8,1)-1 -> 46418 | E8: =B8 -> 1
B9: 2 | C9: =EDATE(C8,1) -> 46419 | D9: =EDATE(C9,1)-1 -> 46446 | E9: =B9 -> 2
B10: 3 | C10: =EDATE(C9,1) -> 46447 | D10: =EDATE(C10,1)-1 -> 46477 | E10: =B10 -> 3
B11: 4 | C11: =EDATE(C10,1) -> 46478 | D11: =EDATE(C11,1)-1 -> 46507 | E11: =B11 -> 4
B12: 5 | C12: =EDATE(C11,1) -> 46508 | D12: =EDATE(C12,1)-1 -> 46538 | E12: =B12 -> 5
B13: 6 | C13: =EDATE(C12,1) -> 46539 | D13: =EDATE(C13,1)-1 -> 46568 | E13: =B13 -> 6
B14: 7 | C14: =EDATE(C13,1) -> 46569 | D14: =EDATE(C14,1)-1 -> 46599 | E14: =B14 -> 7
B15: 8 | C15: =EDATE(C14,1) -> 46600 | D15: =EDATE(C15,1)-1 -> 46630 | E15: =B15 -> 8
B16: 9 | C16: =EDATE(C15,1) -> 46631 | D16: =EDATE(C16,1)-1 -> 46660 | E16: =B16 -> 9
B17: 10 | C17: =EDATE(C16,1) -> 46661 | D17: =EDATE(C17,1)-1 -> 46691 | E17: =B17 -> 10
B18: 11 | C18: =EDATE(C17,1) -> 46692 | D18: =EDATE(C18,1)-1 -> 46721 | E18: =B18 -> 11
B19: 12 | C19: =EDATE(C18,1) -> 46722 | D19: =EDATE(C19,1)-1 -> 46752 | E19: =B19 -> 12
B20: 13 | C20: =EDATE(C19,1) -> 46753 | D20: =EDATE(C20,1)-1 -> 46783 | E20: =B20 -> 13
... B25: 18 | C25: =EDATE(C24,1) -> 46905 | D25: =EDATE(C25,1)-1 -> 46934 | E25: =B25 -> 18
B28: Operating Periods (Semi-Annual, 20 periods = 10-yr Debt Tenor)
B29: Period # | C29: Op. Year | D29: Half | E29: Period Start | F29: Period End | G29: t (yrs since COD, midpoint) | H29: Days in period
B30: 1 | C30: =ROUNDUP(B30/2,0) -> 1 | D30: =IF(MOD(B30,2)=1,"H1","H2") -> H1 | E30: =Assumptions!$F$59 -> 46935 | F30: =EDATE(E30,6)-1 -> 47118 | G30: =((B30-1)+0.5)/2 -> 0.25 | H30: =F30-E30+1 -> 184
B31: 2 | C31: =ROUNDUP(B31/2,0) -> 1 | D31: =IF(MOD(B31,2)=1,"H1","H2") -> H2 | E31: =EDATE(E30,6) -> 47119 | F31: =EDATE(E31,6)-1 -> 47299 | G31: =((B31-1)+0.5)/2 -> 0.75 | H31: =F31-E31+1 -> 181
B32: 3 | C32: =ROUNDUP(B32/2,0) -> 2 | D32: =IF(MOD(B32,2)=1,"H1","H2") -> H1 | E32: =EDATE(E31,6) -> 47300 | F32: =EDATE(E32,6)-1 -> 47483 | G32: =((B32-1)+0.5)/2 -> 1.25 | H32: =F32-E32+1 -> 184
B33: 4 | C33: =ROUNDUP(B33/2,0) -> 2 | D33: =IF(MOD(B33,2)=1,"H1","H2") -> H2 | E33: =EDATE(E32,6) -> 47484 | F33: =EDATE(E33,6)-1 -> 47664 | G33: =((B33-1)+0.5)/2 -> 1.75 | H33: =F33-E33+1 -> 181
B34: 5 | C34: =ROUNDUP(B34/2,0) -> 3 | D34: =IF(MOD(B34,2)=1,"H1","H2") -> H1 | E34: =EDATE(E33,6) -> 47665 | F34: =EDATE(E34,6)-1 -> 47848 | G34: =((B34-1)+0.5)/2 -> 2.25 | H34: =F34-E34+1 -> 184
B35: 6 | C35: =ROUNDUP(B35/2,0) -> 3 | D35: =IF(MOD(B35,2)=1,"H1","H2") -> H2 | E35: =EDATE(E34,6) -> 47849 | F35: =EDATE(E35,6)-1 -> 48029 | G35: =((B35-1)+0.5)/2 -> 2.75 | H35: =F35-E35+1 -> 181
B36: 7 | C36: =ROUNDUP(B36/2,0) -> 4 | D36: =IF(MOD(B36,2)=1,"H1","H2") -> H1 | E36: =EDATE(E35,6) -> 48030 | F36: =EDATE(E36,6)-1 -> 48213 | G36: =((B36-1)+0.5)/2 -> 3.25 | H36: =F36-E36+1 -> 184
B37: 8 | C37: =ROUNDUP(B37/2,0) -> 4 | D37: =IF(MOD(B37,2)=1,"H1","H2") -> H2 | E37: =EDATE(E36,6) -> 48214 | F37: =EDATE(E37,6)-1 -> 48395 | G37: =((B37-1)+0.5)/2 -> 3.75 | H37: =F37-E37+1 -> 182
B38: 9 | C38: =ROUNDUP(B38/2,0) -> 5 | D38: =IF(MOD(B38,2)=1,"H1","H2") -> H1 | E38: =EDATE(E37,6) -> 48396 | F38: =EDATE(E38,6)-1 -> 48579 | G38: =((B38-1)+0.5)/2 -> 4.25 | H38: =F38-E38+1 -> 184
B39: 10 | C39: =ROUNDUP(B39/2,0) -> 5 | D39: =IF(MOD(B39,2)=1,"H1","H2") -> H2 | E39: =EDATE(E38,6) -> 48580 | F39: =EDATE(E39,6)-1 -> 48760 | G39: =((B39-1)+0.5)/2 -> 4.75 | H39: =F39-E39+1 -> 181
B40: 11 | C40: =ROUNDUP(B40/2,0) -> 6 | D40: =IF(MOD(B40,2)=1,"H1","H2") -> H1 | E40: =EDATE(E39,6) -> 48761 | F40: =EDATE(E40,6)-1 -> 48944 | G40: =((B40-1)+0.5)/2 -> 5.25 | H40: =F40-E40+1 -> 184
B41: 12 | C41: =ROUNDUP(B41/2,0) -> 6 | D41: =IF(MOD(B41,2)=1,"H1","H2") -> H2 | E41: =EDATE(E40,6) -> 48945 | F41: =EDATE(E41,6)-1 -> 49125 | G41: =((B41-1)+0.5)/2 -> 5.75 | H41: =F41-E41+1 -> 181
B42: 13 | C42: =ROUNDUP(B42/2,0) -> 7 | D42: =IF(MOD(B42,2)=1,"H1","H2") -> H1 | E42: =EDATE(E41,6) -> 49126 | F42: =EDATE(E42,6)-1 -> 49309 | G42: =((B42-1)+0.5)/2 -> 6.25 | H42: =F42-E42+1 -> 184
... B49: 20 | C49: =ROUNDUP(B49/2,0) -> 10 | D49: =IF(MOD(B49,2)=1,"H1","H2") -> H2 | E49: =EDATE(E48,6) -> 50406 | F49: =EDATE(E49,6)-1 -> 50586 | G49: =((B49-1)+0.5)/2 -> 9.75 | H49: =F49-E49+1 -> 181

Sheet Construction
B2: Construction — Capex Drawdown, Funding Split & IDC
B4: Active Scenario: | C4: =Cover!$C$9 -> Base | D4: <<<< Cover
B5: Base Project Cost
B6: Total Base Capex ($) | D6: =Assumptions!$F$9*Assumptions!$F$36*(1+Assumptions!$F$66) -> 194400000 | F6: Installed capacity x Capex/MT x (1+contingency%) -- Active scenario
B8: Monthly Drawdown Schedule (Month 1 - 18)
B9: Month # | C9: Date | D9: Capex Draw % (S-curve input) | E9: Capex Draw $ | F9: Debt Draw $ (Gearing x Capex) | G9: Equity Draw $ | H9: Opening Debt Balance | I9: IDC accrued (capitalised) | J9: Closing Debt Balance | K9: Mezz Draw $ (% of Capex) | L9: Mezz Opening Balance | M9: Mezz IDC accrued (capitalised) | N9: Mezz Closing Balance
B10: =Timing!B8 -> 1 | C10: =Timing!C8 -> 46388 | D10: 0.01 | E10: =D10*$D$6 -> 1944000 | F10: =E10*Assumptions!$F$46 -> 1166400 | G10: =E10-F10-K10 -> 486000 | H10: =IF(B10=1,0,J9) -> 0 | I10: =H10*Assumptions!$F$42/12 -> 0 | J10: =H10+F10+I10 -> 1166400 | K10: =E10*Assumptions!$F$75 -> 291600 | L10: =IF(B10=1,0,N9) -> 0 | M10: =L10*Assumptions!$F$76/12 -> 0 | N10: =L10+K10+M10 -> 291600
B11: =Timing!B9 -> 2 | C11: =Timing!C9 -> 46419 | D11: 0.02 | E11: =D11*$D$6 -> 3888000 | F11: =E11*Assumptions!$F$46 -> 2332800 | G11: =E11-F11-K11 -> 972000 | H11: =IF(B11=1,0,J10) -> 1166400 | I11: =H11*Assumptions!$F$42/12 -> 9234 | J11: =H11+F11+I11 -> 3508434 | K11: =E11*Assumptions!$F$75 -> 583200 | L11: =IF(B11=1,0,N10) -> 291600 | M11: =L11*Assumptions!$F$76/12 -> 3402 | N11: =L11+K11+M11 -> 878202
B12: =Timing!B10 -> 3 | C12: =Timing!C10 -> 46447 | D12: 0.03 | E12: =D12*$D$6 -> 5832000 | F12: =E12*Assumptions!$F$46 -> 3499200 | G12: =E12-F12-K12 -> 1458000 | H12: =IF(B12=1,0,J11) -> 3508434 | I12: =H12*Assumptions!$F$42/12 -> 27775.102 | J12: =H12+F12+I12 -> 7035409.1 | K12: =E12*Assumptions!$F$75 -> 874800 | L12: =IF(B12=1,0,N11) -> 878202 | M12: =L12*Assumptions!$F$76/12 -> 10245.69 | N12: =L12+K12+M12 -> 1763247.7
B13: =Timing!B11 -> 4 | C13: =Timing!C11 -> 46478 | D13: 0.04 | E13: =D13*$D$6 -> 7776000 | F13: =E13*Assumptions!$F$46 -> 4665600 | G13: =E13-F13-K13 -> 1944000 | H13: =IF(B13=1,0,J12) -> 7035409.1 | I13: =H13*Assumptions!$F$42/12 -> 55696.989 | J13: =H13+F13+I13 -> 11756706 | K13: =E13*Assumptions!$F$75 -> 1166400 | L13: =IF(B13=1,0,N12) -> 1763247.7 | M13: =L13*Assumptions!$F$76/12 -> 20571.223 | N13: =L13+K13+M13 -> 2950218.9
B14: =Timing!B12 -> 5 | C14: =Timing!C12 -> 46508 | D14: 0.06 | E14: =D14*$D$6 -> 11664000 | F14: =E14*Assumptions!$F$46 -> 6998400 | G14: =E14-F14-K14 -> 2916000 | H14: =IF(B14=1,0,J13) -> 11756706 | I14: =H14*Assumptions!$F$42/12 -> 93073.923 | J14: =H14+F14+I14 -> 18848180 | K14: =E14*Assumptions!$F$75 -> 1749600 | L14: =IF(B14=1,0,N13) -> 2950218.9 | M14: =L14*Assumptions!$F$76/12 -> 34419.221 | N14: =L14+K14+M14 -> 4734238.1
B15: =Timing!B13 -> 6 | C15: =Timing!C13 -> 46539 | D15: 0.07 | E15: =D15*$D$6 -> 13608000 | F15: =E15*Assumptions!$F$46 -> 8164800 | G15: =E15-F15-K15 -> 3402000 | H15: =IF(B15=1,0,J14) -> 18848180 | I15: =H15*Assumptions!$F$42/12 -> 149214.76 | J15: =H15+F15+I15 -> 27162195 | K15: =E15*Assumptions!$F$75 -> 2041200 | L15: =IF(B15=1,0,N14) -> 4734238.1 | M15: =L15*Assumptions!$F$76/12 -> 55232.778 | N15: =L15+K15+M15 -> 6830670.9
B16: =Timing!B14 -> 7 | C16: =Timing!C14 -> 46569 | D16: 0.08 | E16: =D16*$D$6 -> 15552000 | F16: =E16*Assumptions!$F$46 -> 9331200 | G16: =E16-F16-K16 -> 3888000 | H16: =IF(B16=1,0,J15) -> 27162195 | I16: =H16*Assumptions!$F$42/12 -> 215034.04 | J16: =H16+F16+I16 -> 36708429 | K16: =E16*Assumptions!$F$75 -> 2332800 | L16: =IF(B16=1,0,N15) -> 6830670.9 | M16: =L16*Assumptions!$F$76/12 -> 79691.161 | N16: =L16+K16+M16 -> 9243162.1
B17: =Timing!B15 -> 8 | C17: =Timing!C15 -> 46600 | D17: 0.09 | E17: =D17*$D$6 -> 17496000 | F17: =E17*Assumptions!$F$46 -> 10497600 | G17: =E17-F17-K17 -> 4374000 | H17: =IF(B17=1,0,J16) -> 36708429 | I17: =H17*Assumptions!$F$42/12 -> 290608.39 | J17: =H17+F17+I17 -> 47496637 | K17: =E17*Assumptions!$F$75 -> 2624400 | L17: =IF(B17=1,0,N16) -> 9243162.1 | M17: =L17*Assumptions!$F$76/12 -> 107836.89 | N17: =L17+K17+M17 -> 11975399
B18: =Timing!B16 -> 9 | C18: =Timing!C16 -> 46631 | D18: 0.1 | E18: =D18*$D$6 -> 19440000 | F18: =E18*Assumptions!$F$46 -> 11664000 | G18: =E18-F18-K18 -> 4860000 | H18: =IF(B18=1,0,J17) -> 47496637 | I18: =H18*Assumptions!$F$42/12 -> 376015.04 | J18: =H18+F18+I18 -> 59536652 | K18: =E18*Assumptions!$F$75 -> 2916000 | L18: =IF(B18=1,0,N17) -> 11975399 | M18: =L18*Assumptions!$F$76/12 -> 139712.99 | N18: =L18+K18+M18 -> 15031112
B19: =Timing!B17 -> 10 | C19: =Timing!C17 -> 46661 | D19: 0.1 | E19: =D19*$D$6 -> 19440000 | F19: =E19*Assumptions!$F$46 -> 11664000 | G19: =E19-F19-K19 -> 4860000 | H19: =IF(B19=1,0,J18) -> 59536652 | I19: =H19*Assumptions!$F$42/12 -> 471331.83 | J19: =H19+F19+I19 -> 71671984 | K19: =E19*Assumptions!$F$75 -> 2916000 | L19: =IF(B19=1,0,N18) -> 15031112 | M19: =L19*Assumptions!$F$76/12 -> 175362.97 | N19: =L19+K19+M19 -> 18122475
B20: =Timing!B18 -> 11 | C20: =Timing!C18 -> 46692 | D20: 0.09 | E20: =D20*$D$6 -> 17496000 | F20: =E20*Assumptions!$F$46 -> 10497600 | G20: =E20-F20-K20 -> 4374000 | H20: =IF(B20=1,0,J19) -> 71671984 | I20: =H20*Assumptions!$F$42/12 -> 567403.21 | J20: =H20+F20+I20 -> 82736987 | K20: =E20*Assumptions!$F$75 -> 2624400 | L20: =IF(B20=1,0,N19) -> 18122475 | M20: =L20*Assumptions!$F$76/12 -> 211428.87 | N20: =L20+K20+M20 -> 20958304
B21: =Timing!B19 -> 12 | C21: =Timing!C19 -> 46722 | D21: 0.08 | E21: =D21*$D$6 -> 15552000 | F21: =E21*Assumptions!$F$46 -> 9331200 | G21: =E21-F21-K21 -> 3888000 | H21: =IF(B21=1,0,J20) -> 82736987 | I21: =H21*Assumptions!$F$42/12 -> 655001.15 | J21: =H21+F21+I21 -> 92723188 | K21: =E21*Assumptions!$F$75 -> 2332800 | L21: =IF(B21=1,0,N20) -> 20958304 | M21: =L21*Assumptions!$F$76/12 -> 244513.54 | N21: =L21+K21+M21 -> 23535617
... B27: =Timing!B25 -> 18 | C27: =Timing!C25 -> 46905 | D27: 0.01 | E27: =D27*$D$6 -> 1944000 | F27: =E27*Assumptions!$F$46 -> 1166400 | G27: =E27-F27-K27 -> 486000 | H27: =IF(B27=1,0,J26) -> 1.2264389e+08 | I27: =H27*Assumptions!$F$42/12 -> 970930.82 | J27: =H27+F27+I27 -> 1.2478122e+08 | K27: =E27*Assumptions!$F$75 -> 291600 | L27: =IF(B27=1,0,N26) -> 31552609 | M27: =L27*Assumptions!$F$76/12 -> 368113.77 | N27: =L27+K27+M27 -> 32212323
B29: TOTAL | D29: =SUM(D10:D27) -> 1 | E29: =SUM(E10:E27) -> 194400000 | F29: =SUM(F10:F27) -> 116640000 | G29: =SUM(G10:G27) -> 48600000 | I29: =SUM(I10:I27) -> 8141223.3 | K29: =SUM(K10:K27) -> 29160000 | M29: =SUM(M10:M27) -> 3052322.6
B31: Sources & Uses at COD
B32: USES
B33: Base Plant Capex | D33: =E29 -> 194400000
B34: Capitalised Interest During Construction (IDC) | D34: =I29 -> 8141223.3
B35: Upfront Arrangement Fee (capitalised) | D35: =D45 -> 1749600
B36: DSRA Funding at COD | D36: =Reserves!$C$9 -> 18687488
B37: TOTAL USES | D37: =SUM(D33:D36) -> 2.2297831e+08
B39: SOURCES
B40: Senior Debt at COD (draws + capitalised IDC + fee) | D40: =D46 -> 1.2653082e+08
B41: Base Equity Draws (construction period) | D41: =G29 -> 48600000
B42: Additional Equity — DSRA Funding | D42: =Reserves!$C$9 -> 18687488
B43: TOTAL SOURCES | D43: =SUM(D40:D42) -> 1.9381831e+08
B45: Upfront Fee (% of debt draws, capitalised) | D45: =F29*Assumptions!$F$43 -> 1749600
B46: Total Debt at COD (draws + capitalised IDC + fee) | D46: =F29+I29+D45 -> 1.2653082e+08
B47: Achieved gearing at COD (Debt / (Debt+Base Equity)) | D47: =D46/(D46+G29) -> 0.72249317
B49: Sources minus Uses check (must = 0) | D49: =D43-D37+D53 -> 0
B52: Capitalised Interest During Construction — Mezzanine | D52: =M29 -> 3052322.6
B53: VAT Bridge Amount (import VAT on capex, self-funding) | D53: =E29*Assumptions!$F$67 -> 29160000
B54: TOTAL USES (incl. mezzanine IDC & VAT bridge) | D54: =D37+D52+D53 -> 2.5519063e+08
B56: Mezzanine Debt at COD (draws + capitalised interest) | D56: =K29+M29 -> 32212323
...

Sheet Operations
B2: Operations — Plant, Bean Procurement (GHS) & Product Sales (USD)
B4: 20 semi-annual periods (Year 1 = periods 1-2, ... Year 10 = periods 19-20). All prices/costs escalate from COD using period-midpoint 't'.
B5: Active Scenario: | C5: =Cover!$C$9 -> Base | D5: <<<< Cover
B6: Timing
B7: Period # | C7: 1 | D7: 2 | E7: 3 | F7: 4 | G7: 5 | H7: 6 | I7: 7 | J7: 8 | K7: 9 | L7: 10 | M7: 11 | N7: 12 | O7: 13 | P7: 14 | Q7: 15 | R7: 16 | S7: 17 | T7: 18 | U7: 19 | V7: 20
B8: Operating Year | C8: =Timing!C30 -> 1 | D8: =Timing!C31 -> 1 | E8: =Timing!C32 -> 2 | F8: =Timing!C33 -> 2 | G8: =Timing!C34 -> 3 | H8: =Timing!C35 -> 3 | I8: =Timing!C36 -> 4 | J8: =Timing!C37 -> 4 | K8: =Timing!C38 -> 5 | L8: =Timing!C39 -> 5 | M8: =Timing!C40 -> 6 | N8: =Timing!C41 -> 6 | O8: =Timing!C42 -> 7 | P8: =Timing!C43 -> 7 | Q8: =Timing!C44 -> 8 | R8: =Timing!C45 -> 8 | S8: =Timing!C46 -> 9 | T8: =Timing!C47 -> 9 | U8: =Timing!C48 -> 10 | V8: =Timing!C49 -> 10
B9: Half | C9: =Timing!D30 -> H1 | D9: =Timing!D31 -> H2 | E9: =Timing!D32 -> H1 | F9: =Timing!D33 -> H2 | G9: =Timing!D34 -> H1 | H9: =Timing!D35 -> H2 | I9: =Timing!D36 -> H1 | J9: =Timing!D37 -> H2 | K9: =Timing!D38 -> H1 | L9: =Timing!D39 -> H2 | M9: =Timing!D40 -> H1 | N9: =Timing!D41 -> H2 | O9: =Timing!D42 -> H1 | P9: =Timing!D43 -> H2 | Q9: =Timing!D44 -> H1 | R9: =Timing!D45 -> H2 | S9: =Timing!D46 -> H1 | T9: =Timing!D47 -> H2 | U9: =Timing!D48 -> H1 | V9: =Timing!D49 -> H2
B10: t (yrs since COD, midpoint) | C10: =Timing!G30 -> 0.25 | D10: =Timing!G31 -> 0.75 | E10: =Timing!G32 -> 1.25 | F10: =Timing!G33 -> 1.75 | G10: =Timing!G34 -> 2.25 | H10: =Timing!G35 -> 2.75 | I10: =Timing!G36 -> 3.25 | J10: =Timing!G37 -> 3.75 | K10: =Timing!G38 -> 4.25 | L10: =Timing!G39 -> 4.75 | M10: =Timing!G40 -> 5.25 | N10: =Timing!G41 -> 5.75 | O10: =Timing!G42 -> 6.25 | P10: =Timing!G43 -> 6.75 | Q10: =Timing!G44 -> 7.25 | R10: =Timing!G45 -> 7.75 | S10: =Timing!G46 -> 8.25 | T10: =Timing!G47 -> 8.75 | U10: =Timing!G48 -> 9.25 | V10: =Timing!G49 -> 9.75
B11: Plant Throughput
B12: Utilisation (% of installed capacity) | C12: =IF(C8=1,Assumptions!$F$10*IF(C9="H1",Assumptions!$F$94,Assumptions!$F$95),IF(C8=2,Assumptions!$F$11,Assumptions!$F$12)) -> 0.42 | D12: =IF(D8=1,Assumptions!$F$10*IF(D9="H1",Assumptions!$F$94,Assumptions!$F$95),IF(D8=2,Assumptions!$F$11,Assumptions!$F$12)) -> 0.78 | E12: =IF(E8=1,Assumptions!$F$10*IF(E9="H1",Assumptions!$F$94,Assumptions!$F$95),IF(E8=2,Assumptions!$F$11,Assumptions!$F$12)) -> 0.8 | F12: =IF(F8=1,Assumptions!$F$10*IF(F9="H1",Assumptions!$F$94,Assumptions!$F$95),IF(F8=2,Assumptions!$F$11,Assumptions!$F$12)) -> 0.8 | G12: =IF(G8=1,Assumptions!$F$10*IF(G9="H1",Assumptions!$F$94,Assumptions!$F$95),IF(G8=2,Assumptions!$F$11,Assumptions!$F$12)) -> 0.95 | H12: =IF(H8=1,Assumptions!$F$10*IF(H9="H1",Assumptions!$F$94,Assumptions!$F$95),IF(H8=2,Assumptions!$F$11,Assumptions!$F$12)) -> 0.95 | I12: =IF(I8=1,Assumptions!$F$10*IF(I9="H1",Assumptions!$F$94,Assumptions!$F$95),IF(I8=2,Assumptions!$F$11,Assumptions!$F$12)) -> 0.95 | J12: =IF(J8=1,Assumptions!$F$10*IF(J9="H1",Assumptions!$F$94,Assumptions!$F$95),IF(J8=2,Assumptions!$F$11,Assumptions!$F$12)) -> 0.95 | ... V12: =IF(V8=1,Assumptions!$F$10*IF(V9="H1",Assumptions!$F$94,Assumptions!$F$95),IF(V8=2,Assumptions!$F$11,Assumptions!$F$12)) -> 0.95
B13: Beans processed (MT) | C13: =C12*Assumptions!$F$9/2 -> 3150 | D13: =D12*Assumptions!$F$9/2 -> 5850 | E13: =E12*Assumptions!$F$9/2 -> 6000 | F13: =F12*Assumptions!$F$9/2 -> 6000 | G13: =G12*Assumptions!$F$9/2 -> 7125 | H13: =H12*Assumptions!$F$9/2 -> 7125 | I13: =I12*Assumptions!$F$9/2 -> 7125 | J13: =J12*Assumptions!$F$9/2 -> 7125 | ... V13: =V12*Assumptions!$F$9/2 -> 7125
B14: Total product output (MT) | C14: =C13*Assumptions!$F$13 -> 2677.5 | D14: =D13*Assumptions!$F$13 -> 4972.5 | E14: =E13*Assumptions!$F$13 -> 5100 | F14: =F13*Assumptions!$F$13 -> 5100 | G14: =G13*Assumptions!$F$13 -> 6056.25 | H14: =H13*Assumptions!$F$13 -> 6056.25 | I14: =I13*Assumptions!$F$13 -> 6056.25 | J14: =J13*Assumptions!$F$13 -> 6056.25 | ... V14: =V13*Assumptions!$F$13 -> 6056.25
B15: Cocoa liquor output (MT) | C15: =C14*Assumptions!$F$15 -> 1071 | D15: =D14*Assumptions!$F$15 -> 1989 | E15: =E14*Assumptions!$F$15 -> 2040 | F15: =F14*Assumptions!$F$15 -> 2040 | G15: =G14*Assumptions!$F$15 -> 2422.5 | H15: =H14*Assumptions!$F$15 -> 2422.5 | I15: =I14*Assumptions!$F$15 -> 2422.5 | J15: =J14*Assumptions!$F$15 -> 2422.5 | ... V15: =V14*Assumptions!$F$15 -> 2422.5
B16: Cocoa butter output (MT) | C16: =C14*Assumptions!$F$16 -> 803.25 | D16: =D14*Assumptions!$F$16 -> 1491.75 | E16: =E14*Assumptions!$F$16 -> 1530 | F16: =F14*Assumptions!$F$16 -> 1530 | G16: =G14*Assumptions!$F$16 -> 1816.875 | H16: =H14*Assumptions!$F$16 -> 1816.875 | I16: =I14*Assumptions!$F$16 -> 1816.875 | J16: =J14*Assumptions!$F$16 -> 1816.875 | ... V16: =V14*Assumptions!$F$16 -> 1816.875
B17: Cocoa cake/powder output (MT) | C17: =C14*Assumptions!$F$17 -> 803.25 | D17: =D14*Assumptions!$F$17 -> 1491.75 | E17: =E14*Assumptions!$F$17 -> 1530 | F17: =F14*Assumptions!$F$17 -> 1530 | G17: =G14*Assumptions!$F$17 -> 1816.875 | H17: =H14*Assumptions!$F$17 -> 1816.875 | I17: =I14*Assumptions!$F$17 -> 1816.875 | J17: =J14*Assumptions!$F$17 -> 1816.875 | ... V17: =V14*Assumptions!$F$17 -> 1816.875
B18: Product Pricing & Revenue (USD, ICE-Linked)
B19: ICE cocoa benchmark price (t) ($/MT) | C19: =Assumptions!$F$20*(1+Assumptions!$F$49)^C10 -> 7038.1864 | D19: =Assumptions!$F$20*(1+Assumptions!$F$49)^D10 -> 7115.1853 | E19: =Assumptions!$F$20*(1+Assumptions!$F$49)^E10 -> 7193.0265 | F19: =Assumptions!$F$20*(1+Assumptions!$F$49)^F10 -> 7271.7193 | G19: =Assumptions!$F$20*(1+Assumptions!$F$49)^G10 -> 7351.2731 | H19: =Assumptions!$F$20*(1+Assumptions!$F$49)^H10 -> 7431.6972 | I19: =Assumptions!$F$20*(1+Assumptions!$F$49)^I10 -> 7513.0011 | J19: =Assumptions!$F$20*(1+Assumptions!$F$49)^J10 -> 7595.1945 | ... V19: =Assumptions!$F$20*(1+Assumptions!$F$49)^V10 -> 8654.5457
B20: Liquor price - contracted ($/MT) | C20: =MAX((Assumptions!$F$97*(Assumptions!$F$20+Assumptions!$F$21)*(1+Assumptions!$F$49)^C10),C19+(Assumptions!$F$21*(1+IF(C8>=Assumptions!$F$99,Assumptions!$F$100,0)))) -> 7438.1864 | D20: =MAX((Assumptions!$F$97*(Assumptions!$F$20+Assumptions!$F$21)*(1+Assumptions!$F$49)^D10),D19+(Assumptions!$F$21*(1+IF(D8>=Assumptions!$F$99,Assumptions!$F$100,0)))) -> 7515.1853 | E20: =MAX((Assumptions!$F$97*(Assumptions!$F$20+Assumptions!$F$21)*(1+Assumptions!$F$49)^E10),E19+(Assumptions!$F$21*(1+IF(E8>=Assumptions!$F$99,Assumptions!$F$100,0)))) -> 7593.0265 | F20: =MAX((Assumptions!$F$97*(Assumptions!$F$20+Assumptions!$F$21)*(1+Assumptions!$F$49)^F10),F19+(Assumptions!$F$21*(1+IF(F8>=Assumptions!$F$99,Assumptions!$F$100,0)))) -> 7671.7193 | G20: =MAX((Assumptions!$F$97*(Assumptions!$F$20+Assumptions!$F$21)*(1+Assumptions!$F$49)^G10),G19+(Assumptions!$F$21*(1+IF(G8>=Assumptions!$F$99,Assumptions!$F$100,0)))) -> 7751.2731 | H20: =MAX((Assumptions!$F$97*(Assumptions!$F$20+Assumptions!$F$21)*(1+Assumptions!$F$49)^H10),H19+(Assumptions!$F$21*(1+IF(H8>=Assumptions!$F$99,Assumptions!$F$100,0)))) -> 7831.6972 | I20: =MAX((Assumptions!$F$97*(Assumptions!$F$20+Assumptions!$F$21)*(1+Assumptions!$F$49)^I10),I19+(Assumptions!$F$21*(1+IF(I8>=Assumptions!$F$99,Assumptions!$F$100,0)))) -> 7913.0011 | J20: =MAX((Assumptions!$F$97*(Assumptions!$F$20+Assumptions!$F$21)*(1+Assumptions!$F$49)^J10),J19+(Assumptions!$F$21*(1+IF(J8>=Assumptions!$F$99,Assumptions!$F$100,0)))) -> 7995.1945 | ... V20: =MAX((Assumptions!$F$97*(Assumptions!$F$20+Assumptions!$F$21)*(1+Assumptions!$F$49)^V10),V19+(Assumptions!$F$21*(1+IF(V8>=Assumptions!$F$99,Assumptions!$F$100,0)))) -> 9014.5457
B21: Liquor price - spot ($/MT) | C21: =C19+Assumptions!$F$21*Assumptions!$F$26 -> 7238.1864 | D21: =D19+Assumptions!$F$21*Assumptions!$F$26 -> 7315.1853 | E21: =E19+Assumptions!$F$21*Assumptions!$F$26 -> 7393.0265 | F21: =F19+Assumptions!$F$21*Assumptions!$F$26 -> 7471.7193 | G21: =G19+Assumptions!$F$21*Assumptions!$F$26 -> 7551.2731 | H21: =H19+Assumptions!$F$21*Assumptions!$F$26 -> 7631.6972 | I21: =I19+Assumptions!$F$21*Assumptions!$F$26 -> 7713.0011 | J21: =J19+Assumptions!$F$21*Assumptions!$F$26 -> 7795.1945 | ... V21: =V19+Assumptions!$F$21*Assumptions!$F$26 -> 8854.5457
B22: Butter price - contracted ($/MT) | C22: =MAX((Assumptions!$F$97*(Assumptions!$F$20+Assumptions!$F$22)*(1+Assumptions!$F$49)^C10),C19+(Assumptions!$F$22*(1+IF(C8>=Assumptions!$F$99,Assumptions!$F$100,0)))) -> 8838.1864 | D22: =MAX((Assumptions!$F$97*(Assumptions!$F$20+Assumptions!$F$22)*(1+Assumptions!$F$49)^D10),D19+(Assumptions!$F$22*(1+IF(D8>=Assumptions!$F$99,Assumptions!$F$100,0)))) -> 8915.1853 | E22: =MAX((Assumptions!$F$97*(Assumptions!$F$20+Assumptions!$F$22)*(1+Assumptions!$F$49)^E10),E19+(Assumptions!$F$22*(1+IF(E8>=Assumptions!$F$99,Assumptions!$F$100,0)))) -> 8993.0265 | F22: =MAX((Assumptions!$F$97*(Assumptions!$F$20+Assumptions!$F$22)*(1+Assumptions!$F$49)^F10),F19+(Assumptions!$F$22*(1+IF(F8>=Assumptions!$F$99,Assumptions!$F$100,0)))) -> 9071.7193 | G22: =MAX((Assumptions!$F$97*(Assumptions!$F$20+Assumptions!$F$22)*(1+Assumptions!$F$49)^G10),G19+(Assumptions!$F$22*(1+IF(G8>=Assumptions!$F$99,Assumptions!$F$100,0)))) -> 9151.2731 | H22: =MAX((Assumptions!$F$97*(Assumptions!$F$20+Assumptions!$F$22)*(1+Assumptions!$F$49)^H10),H19+(Assumptions!$F$22*(1+IF(H8>=Assumptions!$F$99,Assumptions!$F$100,0)))) -> 9231.6972 | I22: =MAX((Assumptions!$F$97*(Assumptions!$F$20+Assumptions!$F$22)*(1+Assumptions!$F$49)^I10),I19+(Assumptions!$F$22*(1+IF(I8>=Assumptions!$F$99,Assumptions!$F$100,0)))) -> 9313.0011 | J22: =MAX((Assumptions!$F$97*(Assumptions!$F$20+Assumptions!$F$22)*(1+Assumptions!$F$49)^J10),J19+(Assumptions!$F$22*(1+IF(J8>=Assumptions!$F$99,Assumptions!$F$100,0)))) -> 9395.1945 | ... V22: =MAX((Assumptions!$F$97*(Assumptions!$F$20+Assumptions!$F$22)*(1+Assumptions!$F$49)^V10),V19+(Assumptions!$F$22*(1+IF(V8>=Assumptions!$F$99,Assumptions!$F$100,0)))) -> 10274.546
B23: Butter price - spot ($/MT) | C23: =C19+Assumptions!$F$22*Assumptions!$F$26 -> 7938.1864 | D23: =D19+Assumptions!$F$22*Assumptions!$F$26 -> 8015.1853 | E23: =E19+Assumptions!$F$22*Assumptions!$F$26 -> 8093.0265 | F23: =F19+Assumptions!$F$22*Assumptions!$F$26 -> 8171.7193 | G23: =G19+Assumptions!$F$22*Assumptions!$F$26 -> 8251.2731 | H23: =H19+Assumptions!$F$22*Assumptions!$F$26 -> 8331.6972 | I23: =I19+Assumptions!$F$22*Assumptions!$F$26 -> 8413.0011 | J23: =J19+Assumptions!$F$22*Assumptions!$F$26 -> 8495.1945 | ... V23: =V19+Assumptions!$F$22*Assumptions!$F$26 -> 9554.5457
B24: Cake/powder price - contracted ($/MT) | C24: =MAX((Assumptions!$F$97*(Assumptions!$F$20+Assumptions!$F$23)*(1+Assumptions!$F$49)^C10),C19+(Assumptions!$F$23*(1+IF(C8>=Assumptions!$F$99,Assumptions!$F$100,0)))) -> 6738.1864 | D24: =MAX((Assumptions!$F$97*(Assumptions!$F$20+Assumptions!$F$23)*(1+Assumptions!$F$49)^D10),D19+(Assumptions!$F$23*(1+IF(D8>=Assumptions!$F$99,Assumptions!$F$100,0)))) -> 6815.1853 | E24: =MAX((Assumptions!$F$97*(Assumptions!$F$20+Assumptions!$F$23)*(1+Assumptions!$F$49)^E10),E19+(Assumptions!$F$23*(1+IF(E8>=Assumptions!$F$99,Assumptions!$F$100,0)))) -> 6893.0265 | F24: =MAX((Assumptions!$F$97*(Assumptions!$F$20+Assumptions!$F$23)*(1+Assumptions!$F$49)^F10),F19+(Assumptions!$F$23*(1+IF(F8>=Assumptions!$F$99,Assumptions!$F$100,0)))) -> 6971.7193 | G24: =MAX((Assumptions!$F$97*(Assumptions!$F$20+Assumptions!$F$23)*(1+Assumptions!$F$49)^G10),G19+(Assumptions!$F$23*(1+IF(G8>=Assumptions!$F$99,Assumptions!$F$100,0)))) -> 7051.2731 | H24: =MAX((Assumptions!$F$97*(Assumptions!$F$20+Assumptions!$F$23)*(1+Assumptions!$F$49)^H10),H19+(Assumptions!$F$23*(1+IF(H8>=Assumptions!$F$99,Assumptions!$F$100,0)))) -> 7131.6972 | I24: =MAX((Assumptions!$F$97*(Assumptions!$F$20+Assumptions!$F$23)*(1+Assumptions!$F$49)^I10),I19+(Assumptions!$F$23*(1+IF(I8>=Assumptions!$F$99,Assumptions!$F$100,0)))) -> 7213.0011 | J24: =MAX((Assumptions!$F$97*(Assumptions!$F$20+Assumptions!$F$23)*(1+Assumptions!$F$49)^J10),J19+(Assumptions!$F$23*(1+IF(J8>=Assumptions!$F$99,Assumptions!$F$100,0)))) -> 7295.1945 | ... V24: =MAX((Assumptions!$F$97*(Assumptions!$F$20+Assumptions!$F$23)*(1+Assumptions!$F$49)^V10),V19+(Assumptions!$F$23*(1+IF(V8>=Assumptions!$F$99,Assumptions!$F$100,0)))) -> 8384.5457
B25: Cake/powder price - spot ($/MT) | C25: =C19+Assumptions!$F$23*Assumptions!$F$26 -> 6888.1864 | D25: =D19+Assumptions!$F$23*Assumptions!$F$26 -> 6965.1853 | E25: =E19+Assumptions!$F$23*Assumptions!$F$26 -> 7043.0265 | F25: =F19+Assumptions!$F$23*Assumptions!$F$26 -> 7121.7193 | G25: =G19+Assumptions!$F$23*Assumptions!$F$26 -> 7201.2731 | H25: =H19+Assumptions!$F$23*Assumptions!$F$26 -> 7281.6972 | I25: =I19+Assumptions!$F$23*Assumptions!$F$26 -> 7363.0011 | J25: =J19+Assumptions!$F$23*Assumptions!$F$26 -> 7445.1945 | ... V25: =V19+Assumptions!$F$23*Assumptions!$F$26 -> 8504.5457
B26: Liquor revenue ($) | C26: =(MAX((C15*Assumptions!$F$24),((Assumptions!$F$9/2*Assumptions!$F$13)*Assumptions!$F$15*Assumptions!$F$24*Assumptions!$F$98)))*C20+((C15*Assumptions!$F$25))*C21 -> 15206930 | D26: =(MAX((D15*Assumptions!$F$24),((Assumptions!$F$9/2*Assumptions!$F$13)*Assumptions!$F$15*Assumptions!$F$24*Assumptions!$F$98)))*D20+((D15*Assumptions!$F$25))*D21 -> 16707861 | E26: =(MAX((E15*Assumptions!$F$24),((Assumptions!$F$9/2*Assumptions!$F$13)*Assumptions!$F$15*Assumptions!$F$24*Assumptions!$F$98)))*E20+((E15*Assumptions!$F$25))*E21 -> 16957151 | F26: =(MAX((F15*Assumptions!$F$24),((Assumptions!$F$9/2*Assumptions!$F$13)*Assumptions!$F$15*Assumptions!$F$24*Assumptions!$F$98)))*F20+((F15*Assumptions!$F$25))*F21 -> 17133738 | G26: =(MAX((G15*Assumptions!$F$24),((Assumptions!$F$9/2*Assumptions!$F$13)*Assumptions!$F$15*Assumptions!$F$24*Assumptions!$F$98)))*G20+((G15*Assumptions!$F$25))*G21 -> 18680559 | H26: =(MAX((H15*Assumptions!$F$24),((Assumptions!$F$9/2*Assumptions!$F$13)*Assumptions!$F$15*Assumptions!$F$24*Assumptions!$F$98)))*H20+((H15*Assumptions!$F$25))*H21 -> 18875386 | I26: =(MAX((I15*Assumptions!$F$24),((Assumptions!$F$9/2*Assumptions!$F$13)*Assumptions!$F$15*Assumptions!$F$24*Assumptions!$F$98)))*I20+((I15*Assumptions!$F$25))*I21 -> 19072345 | J26: =(MAX((J15*Assumptions!$F$24),((Assumptions!$F$9/2*Assumptions!$F$13)*Assumptions!$F$15*Assumptions!$F$24*Assumptions!$F$98)))*J20+((J15*Assumptions!$F$25))*J21 -> 19271459 | ... V26: =(MAX((V15*Assumptions!$F$24),((Assumptions!$F$9/2*Assumptions!$F$13)*Assumptions!$F$15*Assumptions!$F$24*Assumptions!$F$98)))*V20+((V15*Assumptions!$F$25))*V21 -> 21760217
B27: Butter revenue ($) | C27: =(MAX((C16*Assumptions!$F$24),((Assumptions!$F$9/2*Assumptions!$F$13)*Assumptions!$F$16*Assumptions!$F$24*Assumptions!$F$98)))*C22+((C16*Assumptions!$F$25))*C23 -> 13445452 | D27: =(MAX((D16*Assumptions!$F$24),((Assumptions!$F$9/2*Assumptions!$F$13)*Assumptions!$F$16*Assumptions!$F$24*Assumptions!$F$98)))*D22+((D16*Assumptions!$F$25))*D23 -> 14667541 | E27: =(MAX((E16*Assumptions!$F$24),((Assumptions!$F$9/2*Assumptions!$F$13)*Assumptions!$F$16*Assumptions!$F$24*Assumptions!$F$98)))*E22+((E16*Assumptions!$F$25))*E23 -> 14859864 | F27: =(MAX((F16*Assumptions!$F$24),((Assumptions!$F$9/2*Assumptions!$F$13)*Assumptions!$F$16*Assumptions!$F$24*Assumptions!$F$98)))*F22+((F16*Assumptions!$F$25))*F23 -> 14992304 | G27: =(MAX((G16*Assumptions!$F$24),((Assumptions!$F$9/2*Assumptions!$F$13)*Assumptions!$F$16*Assumptions!$F$24*Assumptions!$F$98)))*G22+((G16*Assumptions!$F$25))*G23 -> 16299682 | H27: =(MAX((H16*Assumptions!$F$24),((Assumptions!$F$9/2*Assumptions!$F$13)*Assumptions!$F$16*Assumptions!$F$24*Assumptions!$F$98)))*H22+((H16*Assumptions!$F$25))*H23 -> 16445802 | I27: =(MAX((I16*Assumptions!$F$24),((Assumptions!$F$9/2*Assumptions!$F$13)*Assumptions!$F$16*Assumptions!$F$24*Assumptions!$F$98)))*I22+((I16*Assumptions!$F$25))*I23 -> 16593521 | J27: =(MAX((J16*Assumptions!$F$24),((Assumptions!$F$9/2*Assumptions!$F$13)*Assumptions!$F$16*Assumptions!$F$24*Assumptions!$F$98)))*J22+((J16*Assumptions!$F$25))*J23 -> 16742856 | ... V27: =(MAX((V16*Assumptions!$F$24),((Assumptions!$F$9/2*Assumptions!$F$13)*Assumptions!$F$16*Assumptions!$F$24*Assumptions!$F$98)))*V22+((V16*Assumptions!$F$25))*V23 -> 18405935
B28: Cake/powder revenue ($) | C28: =(MAX((C17*Assumptions!$F$24),((Assumptions!$F$9/2*Assumptions!$F$13)*Assumptions!$F$17*Assumptions!$F$24*Assumptions!$F$98)))*C24+((C17*Assumptions!$F$25))*C25 -> 10385070 | D28: =(MAX((D17*Assumptions!$F$24),((Assumptions!$F$9/2*Assumptions!$F$13)*Assumptions!$F$17*Assumptions!$F$24*Assumptions!$F$98)))*D24+((D17*Assumptions!$F$25))*D25 -> 11462573 | E28: =(MAX((E17*Assumptions!$F$24),((Assumptions!$F$9/2*Assumptions!$F$13)*Assumptions!$F$17*Assumptions!$F$24*Assumptions!$F$98)))*E24+((E17*Assumptions!$F$25))*E25 -> 11646864 | F28: =(MAX((F17*Assumptions!$F$24),((Assumptions!$F$9/2*Assumptions!$F$13)*Assumptions!$F$17*Assumptions!$F$24*Assumptions!$F$98)))*F24+((F17*Assumptions!$F$25))*F25 -> 11779304 | G28: =(MAX((G17*Assumptions!$F$24),((Assumptions!$F$9/2*Assumptions!$F$13)*Assumptions!$F$17*Assumptions!$F$24*Assumptions!$F$98)))*G24+((G17*Assumptions!$F$25))*G25 -> 12865788 | H28: =(MAX((H17*Assumptions!$F$24),((Assumptions!$F$9/2*Assumptions!$F$13)*Assumptions!$F$17*Assumptions!$F$24*Assumptions!$F$98)))*H24+((H17*Assumptions!$F$25))*H25 -> 13011909 | I28: =(MAX((I17*Assumptions!$F$24),((Assumptions!$F$9/2*Assumptions!$F$13)*Assumptions!$F$17*Assumptions!$F$24*Assumptions!$F$98)))*I24+((I17*Assumptions!$F$25))*I25 -> 13159628 | J28: =(MAX((J17*Assumptions!$F$24),((Assumptions!$F$9/2*Assumptions!$F$13)*Assumptions!$F$17*Assumptions!$F$24*Assumptions!$F$98)))*J24+((J17*Assumptions!$F$25))*J25 -> 13308963 | ... V28: =(MAX((V17*Assumptions!$F$24),((Assumptions!$F$9/2*Assumptions!$F$13)*Assumptions!$F$17*Assumptions!$F$24*Assumptions!$F$98)))*V24+((V17*Assumptions!$F$25))*V25 -> 15277276
B29: Total Product Revenue ($) | C29: =SUM(C26:C28) -> 39037452 | D29: =SUM(D26:D28) -> 42837975 | E29: =SUM(E26:E28) -> 43463879 | F29: =SUM(F26:F28) -> 43905345 | G29: =SUM(G26:G28) -> 47846029 | H29: =SUM(H26:H28) -> 48333097 | I29: =SUM(I26:I28) -> 48825494 | J29: =SUM(J26:J28) -> 49323278 | ... V29: =SUM(V26:V28) -> 55443428
B30: Bean Procurement (GHS, Converted to USD)
B31: Bean requirement (MT) | C31: =C14*Assumptions!$F$14 -> 3150 | D31: =D14*Assumptions!$F$14 -> 5850 | E31: =E14*Assumptions!$F$14 -> 6000 | F31: =F14*Assumptions!$F$14 -> 6000 | G31: =G14*Assumptions!$F$14 -> 7125 | H31: =H14*Assumptions!$F$14 -> 7125 | I31: =I14*Assumptions!$F$14 -> 7125 | J31: =J14*Assumptions!$F$14 -> 7125 | ... V31: =V14*Assumptions!$F$14 -> 7125
B32: COCOBOD producer price (t) (GHS/64kg bag) | C32: =Assumptions!$F$29*(1+Assumptions!$F$30)^C10*(1+Assumptions!$F$105*((C19/(Assumptions!$F$20*(1+Assumptions!$F$49)^C10))-1)) -> 3086.212 | D32: =Assumptions!$F$29*(1+Assumptions!$F$30)^D10*(1+Assumptions!$F$105*((D19/(Assumptions!$F$20*(1+Assumptions!$F$49)^D10))-1)) -> 3266.1398 | E32: =Assumptions!$F$29*(1+Assumptions!$F$30)^E10*(1+Assumptions!$F$105*((E19/(Assumptions!$F$20*(1+Assumptions!$F$49)^E10))-1)) -> 3456.5575 | F32: =Assumptions!$F$29*(1+Assumptions!$F$30)^F10*(1+Assumptions!$F$105*((F19/(Assumptions!$F$20*(1+Assumptions!$F$49)^F10))-1)) -> 3658.0766 | G32: =Assumptions!$F$29*(1+Assumptions!$F$30)^G10*(1+Assumptions!$F$105*((G19/(Assumptions!$F$20*(1+Assumptions!$F$49)^G10))-1)) -> 3871.3444 | H32: =Assumptions!$F$29*(1+Assumptions!$F$30)^H10*(1+Assumptions!$F$105*((H19/(Assumptions!$F$20*(1+Assumptions!$F$49)^H10))-1)) -> 4097.0458 | I32: =Assumptions!$F$29*(1+Assumptions!$F$30)^I10*(1+Assumptions!$F$105*((I19/(Assumptions!$F$20*(1+Assumptions!$F$49)^I10))-1)) -> 4335.9057 | J32: =Assumptions!$F$29*(1+Assumptions!$F$30)^J10*(1+Assumptions!$F$105*((J19/(Assumptions!$F$20*(1+Assumptions!$F$49)^J10))-1)) -> 4588.6913 | ... V32: =Assumptions!$F$29*(1+Assumptions!$F$30)^V10*(1+Assumptions!$F$105*((V19/(Assumptions!$F$20*(1+Assumptions!$F$49)^V10))-1)) -> 9057.2629
B33: GHS cost per MT beans | C33: =C32/Assumptions!$F$31*1000 -> 48222.063 | D33: =D32/Assumptions!$F$31*1000 -> 51033.435 | E33: =E32/Assumptions!$F$31*1000 -> 54008.711 | F33: =F32/Assumptions!$F$31*1000 -> 57157.447 | G33: =G32/Assumptions!$F$31*1000 -> 60489.756 | H33: =H32/Assumptions!$F$31*1000 -> 64016.34 | I33: =I32/Assumptions!$F$31*1000 -> 67748.527 | J33: =J32/Assumptions!$F$31*1000 -> 71698.301 | ... V33: =V32/Assumptions!$F$31*1000 -> 141519.73
B34: FX rate (t) (GHS per USD) | C34: =Assumptions!$F$32*(1+Assumptions!$F$33)^C10 -> 13.159539 | D34: =Assumptions!$F$32*(1+Assumptions!$F$33)^D10 -> 13.484515 | E34: =Assumptions!$F$32*(1+Assumptions!$F$33)^E10 -> 13.817516 | F34: =Assumptions!$F$32*(1+Assumptions!$F$33)^F10 -> 14.158741 | G34: =Assumptions!$F$32*(1+Assumptions!$F$33)^G10 -> 14.508392 | H34: =Assumptions!$F$32*(1+Assumptions!$F$33)^H10 -> 14.866678 | I34: =Assumptions!$F$32*(1+Assumptions!$F$33)^I10 -> 15.233811 | J34: =Assumptions!$F$32*(1+Assumptions!$F$33)^J10 -> 15.610012 | ... V34: =Assumptions!$F$32*(1+Assumptions!$F$33)^V10 -> 20.918908
B35: Bean cost (GHS) | C35: =C31*C33 -> 1.518995e+08 | D35: =D31*D33 -> 2.9854559e+08 | E35: =E31*E33 -> 3.2405226e+08 | F35: =F31*F33 -> 3.4294468e+08 | G35: =G31*G33 -> 4.3098951e+08 | H35: =H31*H33 -> 4.5611643e+08 | I35: =I31*I33 -> 4.8270825e+08 | J35: =J31*J33 -> 5.108504e+08 | ... V35: =V31*V33 -> 1.0083281e+09
B36: Bean cost (USD) | C36: =C35*((IF(C8<=2,Assumptions!$F$78,0))/Assumptions!$F$32+(1-(IF(C8<=2,Assumptions!$F$78,0)))/C34) -> 11613748 | D36: =D35*((IF(D8<=2,Assumptions!$F$78,0))/Assumptions!$F$32+(1-(IF(D8<=2,Assumptions!$F$78,0)))/D34) -> 22552465 | E36: =E35*((IF(E8<=2,Assumptions!$F$78,0))/Assumptions!$F$32+(1-(IF(E8<=2,Assumptions!$F$78,0)))/E34) -> 24189689 | F36: =F35*((IF(F8<=2,Assumptions!$F$78,0))/Assumptions!$F$32+(1-(IF(F8<=2,Assumptions!$F$78,0)))/F34) -> 25300886 | G36: =G35*((IF(G8<=2,Assumptions!$F$78,0))/Assumptions!$F$32+(1-(IF(G8<=2,Assumptions!$F$78,0)))/G34) -> 29706222 | H36: =H35*((IF(H8<=2,Assumptions!$F$78,0))/Assumptions!$F$32+(1-(IF(H8<=2,Assumptions!$F$78,0)))/H34) -> 30680454 | I36: =I35*((IF(I8<=2,Assumptions!$F$78,0))/Assumptions!$F$32+(1-(IF(I8<=2,Assumptions!$F$78,0)))/I34) -> 31686637 | J36: =J35*((IF(J8<=2,Assumptions!$F$78,0))/Assumptions!$F$32+(1-(IF(J8<=2,Assumptions!$F$78,0)))/J34) -> 32725818 | ... V36: =V35*((IF(V8<=2,Assumptions!$F$78,0))/Assumptions!$F$32+(1-(IF(V8<=2,Assumptions!$F$78,0)))/V34) -> 48201755
B37: Other Operating Costs (USD)
B38: O&M rate (t) ($/MT processed) | C38: =Assumptions!$F$37*(1+Assumptions!$F$49)^C10 -> 955.18244 | D38: =Assumptions!$F$37*(1+Assumptions!$F$49)^D10 -> 965.63228 | E38: =Assumptions!$F$37*(1+Assumptions!$F$49)^E10 -> 976.19645 | F38: =Assumptions!$F$37*(1+Assumptions!$F$49)^F10 -> 986.87619 | G38: =Assumptions!$F$37*(1+Assumptions!$F$49)^G10 -> 997.67277 | H38: =Assumptions!$F$37*(1+Assumptions!$F$49)^H10 -> 1008.5875 | I38: =Assumptions!$F$37*(1+Assumptions!$F$49)^I10 -> 1019.6216 | J38: =Assumptions!$F$37*(1+Assumptions!$F$49)^J10 -> 1030.7764 | ... V38: =Assumptions!$F$37*(1+Assumptions!$F$49)^V10 -> 1174.5455
B39: O&M cost (USD) | C39: =C13*C38 -> 3008824.7 | D39: =D13*D38 -> 5648948.9 | E39: =E13*E38 -> 5857178.7 | F39: =F13*F38 -> 5921257.2 | G39: =G13*G38 -> 7108418.5 | H39: =H13*H38 -> 7186185.7 | I39: =I13*I38 -> 7264803.7 | J39: =J13*J38 -> 7344281.8 | ... V39: =V13*V38 -> 8368636.6
B40: Logistics rate (t) ($/MT product) | C40: =Assumptions!$F$38*(1+Assumptions!$F$49)^C10 -> 45.245484 | D40: =Assumptions!$F$38*(1+Assumptions!$F$49)^D10 -> 45.740477 | E40: =Assumptions!$F$38*(1+Assumptions!$F$49)^E10 -> 46.240885 | F40: =Assumptions!$F$38*(1+Assumptions!$F$49)^F10 -> 46.746767 | G40: =Assumptions!$F$38*(1+Assumptions!$F$49)^G10 -> 47.258184 | H40: =Assumptions!$F$38*(1+Assumptions!$F$49)^H10 -> 47.775196 | I40: =Assumptions!$F$38*(1+Assumptions!$F$49)^I10 -> 48.297864 | J40: =Assumptions!$F$38*(1+Assumptions!$F$49)^J10 -> 48.82625 | ... V40: =Assumptions!$F$38*(1+Assumptions!$F$49)^V10 -> 55.636365
B41: Logistics/freight cost (USD) | C41: =C14*C40 -> 121144.78 | D41: =D14*D40 -> 227444.52 | E41: =E14*E40 -> 235828.51 | F41: =F14*F40 -> 238408.51 | G41: =G14*G40 -> 286207.38 | H41: =H14*H40 -> 289338.53 | I41: =I14*I40 -> 292503.94 | J41: =J14*J40 -> 295703.98 | ... V41: =V14*V40 -> 336947.74
B42: Total Cash Opex (USD) | C42: =C36+C39+C41 -> 14743718 | D42: =D36+D39+D41 -> 28428858 | E42: =E36+E39+E41 -> 30282696 | F42: =F36+F39+F41 -> 31460551 | G42: =G36+G39+G41 -> 37100848 | H42: =H36+H39+H41 -> 38155979 | I42: =I36+I39+I41 -> 39243945 | J42: =J36+J39+J41 -> 40365804 | ... V42: =V36+V39+V41 -> 56907339
...

Sheet Debt
B2: Debt & Financing — Sculpted Senior Term Loan
B4: Repayment each period is sized so scheduled debt service never exceeds CFADS / Target DSCR; final period forces full repayment (bullet true-up).
B5: Active Scenario: | C5: =Cover!$C$9 -> Base | D5: <<<< Cover
B6: Senior Debt Amortisation Schedule (Semi-Annual)
B7: Period # | C7: 1 | D7: 2 | E7: 3 | F7: 4 | G7: 5 | H7: 6 | I7: 7 | J7: 8 | K7: 9 | L7: 10 | M7: 11 | N7: 12 | O7: 13 | P7: 14 | Q7: 15 | R7: 16 | S7: 17 | T7: 18 | U7: 19 | V7: 20
B8: Opening Debt Balance ($) | C8: =Construction!$D$46 -> 1.2653082e+08 | D8: =C14 -> 1.1385355e+08 | E8: =D14 -> 1.0817766e+08 | F8: =E14 -> 1.0317672e+08 | G8: =F14 -> 98504701 | H8: =G14 -> 94918151 | I8: =H14 -> 91598210 | J8: =I14 -> 88578702 | K8: =J14 -> 85895826 | ... V8: =U14 -> 80232210
B9: Interest Expense ($) | C9: =C8*Assumptions!$F$42/2 -> 6010214.1 | D9: =D8*Assumptions!$F$42/2 -> 5408043.6 | E9: =E8*Assumptions!$F$42/2 -> 5138438.7 | F9: =F8*Assumptions!$F$42/2 -> 4900894.4 | G9: =G8*Assumptions!$F$42/2 -> 4678973.3 | H9: =H8*Assumptions!$F$42/2 -> 4508612.1 | I9: =I8*Assumptions!$F$42/2 -> 4350915 | J9: =J8*Assumptions!$F$42/2 -> 4207488.4 | ... V9: =V8*Assumptions!$F$42/2 -> 3811030
B10: CFADS ($) [from Operations] | C10: =Operations!C50 -> 24293734 | D10: =Operations!D50 -> 14409116 | E10: =Operations!E50 -> 13181182 | F10: =Operations!F50 -> 12444794 | G10: =Operations!G50 -> 10745181 | H10: =Operations!H50 -> 10177119 | I10: =Operations!I50 -> 9581549.4 | J10: =Operations!J50 -> 8957474.1 | ... V10: =Operations!V50 -> -1463911
B11: Target Debt Service = CFADS / Target DSCR ($) | C11: =C10/Assumptions!$F$45 -> 18687488 | D11: =D10/Assumptions!$F$45 -> 11083936 | E11: =E10/Assumptions!$F$45 -> 10139371 | F11: =F10/Assumptions!$F$45 -> 9572918.5 | G11: =G10/Assumptions!$F$45 -> 8265523.6 | H11: =H10/Assumptions!$F$45 -> 7828552.7 | I11: =I10/Assumptions!$F$45 -> 7370422.6 | J11: =J10/Assumptions!$F$45 -> 6890364.7 | ... V11: =V10/Assumptions!$F$45 -> -1126085.4
B12: Principal Repayment ($) | C12: =MAX(0,MIN(C8,C11-C9)) -> 12677274 | D12: =MAX(0,MIN(D8,D11-D9)) -> 5675892.1 | E12: =MAX(0,MIN(E8,E11-E9)) -> 5000932.4 | F12: =MAX(0,MIN(F8,F11-F9)) -> 4672024.1 | G12: =MAX(0,MIN(G8,G11-G9)) -> 3586550.3 | H12: =MAX(0,MIN(H8,H11-H9)) -> 3319940.5 | I12: =MAX(0,MIN(I8,I11-I9)) -> 3019507.6 | J12: =MAX(0,MIN(J8,J11-J9)) -> 2682876.3 | ... U12: =MAX(0,MIN(U8,U11-U9)) -> 0 | V12: =V8 -> 80232210
B13: Total Debt Service ($) | C13: =C9+C12 -> 18687488 | D13: =D9+D12 -> 11083936 | E13: =E9+E12 -> 10139371 | F13: =F9+F12 -> 9572918.5 | G13: =G9+G12 -> 8265523.6 | H13: =H9+H12 -> 7828552.7 | I13: =I9+I12 -> 7370422.6 | J13: =J9+J12 -> 6890364.7 | ... V13: =V9+V12 -> 84043240
B14: Closing Debt Balance ($) | C14: =C8-C12 -> 1.1385355e+08 | D14: =D8-D12 -> 1.0817766e+08 | E14: =E8-E12 -> 1.0317672e+08 | F14: =F8-F12 -> 98504701 | G14: =G8-G12 -> 94918151 | H14: =H8-H12 -> 91598210 | I14: =I8-I12 -> 88578702 | J14: =J8-J12 -> 85895826 | ... V14: =V8-V12 -> 0
B15: DSCR (x) | C15: =IFERROR(C10/C13,"n/a") -> 1.3 | D15: =IFERROR(D10/D13,"n/a") -> 1.3 | E15: =IFERROR(E10/E13,"n/a") -> 1.3 | F15: =IFERROR(F10/F13,"n/a") -> 1.3 | G15: =IFERROR(G10/G13,"n/a") -> 1.3 | H15: =IFERROR(H10/H13,"n/a") -> 1.3 | I15: =IFERROR(I10/I13,"n/a") -> 1.3 | J15: =IFERROR(J10/J13,"n/a") -> 1.3 | ... V15: =IFERROR(V10/V13,"n/a") -> -0.017418545
B16: Cumulative Principal Repaid ($) | C16: =C12 -> 12677274 | D16: =C16+D12 -> 18353166 | E16: =D16+E12 -> 23354098 | F16: =E16+F12 -> 28026122 | G16: =F16+G12 -> 31612673 | H16: =G16+H12 -> 34932613 | I16: =H16+I12 -> 37952121 | J16: =I16+J12 -> 40634997 | K16: =J16+K12 -> 42715188 | ... V16: =U16+V12 -> 1.2653082e+08
B18: Credit Metrics & Checks
B19: Minimum DSCR, Periods 1-19 (excl. final bullet) | D19: =MIN(C15:U15) -> -0.10661364
B20: Minimum DSCR, All 20 periods | D20: =MIN(C15:V15) -> -0.10661364
B21: Average DSCR, All periods | D21: =AVERAGE(C15:V15) -> 1.0009806
B22: Debt fully repaid by maturity (Closing Bal. Period 20) | D22: =V14 -> 0
B23: Target minimum DSCR (active scenario) | D23: =Assumptions!$F$45 -> 1.3
B24: Check: Min DSCR (periods 1-19) >= Target | D24: =IF(D19>=D23-0.001,"OK","FAIL") -> FAIL
B26: Loan Life Coverage Ratio (LLCR) & Project Life Coverage Ratio (PLCR) at COD
B27: PV of CFADS, Period 1-20 (discounted @ senior interest rate) | D27: =NPV(Assumptions!$F$42/2,C10:V10) -> 1.1278617e+08
B28: Senior Debt Balance at COD ($) | D28: =Construction!$D$46 -> 1.2653082e+08
B29: LLCR at COD (x) [= PV of CFADS over loan life / Debt at COD] | D29: =D27/D28 -> 0.89137311
B30: PLCR at COD (x) [project life = debt tenor in this model, so PLCR = LLCR] | D30: =D29 -> 0.89137311
B33: Mezzanine Debt Amortisation Schedule (Subordinated, Cash-Sweep)
B34: Period # | C34: 1 | D34: 2 | E34: 3 | F34: 4 | G34: 5 | H34: 6 | I34: 7 | J34: 8 | K34: 9 | L34: 10 | M34: 11 | N34: 12 | O34: 13 | P34: 14 | Q34: 15 | R34: 16 | S34: 17 | T34: 18 | U34: 19 | V34: 20
B35: Opening Mezzanine Balance ($) | C35: =Construction!$D$56 -> 32212323 | D35: =C40 -> 31960416 | E35: =D40 -> 24800130 | F35: =E40 -> 24186107 | G35: =F40 -> 24191449 | H35: =G40 -> 25799625 | I35: =H40 -> 26779723 | J35: =I40 -> 28402375 | K35: =J40 -> 29827998 | ... V35: =U40 -> 62028947
B36: Mezzanine Interest Expense ($) | C36: =C35*Assumptions!$F$76/2 -> 2254862.6 | D36: =D35*Assumptions!$F$76/2 -> 2237229.1 | E36: =E35*Assumptions!$F$76/2 -> 1736009.1 | F36: =F35*Assumptions!$F$76/2 -> 1693027.5 | G36: =G35*Assumptions!$F$76/2 -> 1693401.4 | H36: =H35*Assumptions!$F$76/2 -> 1805973.8 | I36: =I35*Assumptions!$F$76/2 -> 1874580.6 | J36: =J35*Assumptions!$F$76/2 -> 1988166.3 | ... V36: =V35*Assumptions!$F$76/2 -> 4342026.3
B37: Cash Available for Mezz Service (post Senior DS, DSRA, MRA, VAT, NWC & Revolver) ($) | C37: =Waterfall!C30 -> 2506768.8 | D37: =Waterfall!D30 -> 9397515.1 | E37: =Waterfall!E30 -> 2350032.7 | F37: =Waterfall!F30 -> 1687685.1 | G37: =Waterfall!G30 -> 85225.519 | H37: =Waterfall!H30 -> 825875.83 | I37: =Waterfall!I30 -> 251928.41 | J37: =Waterfall!J30 -> 562543.87 | ... V37: =Waterfall!V30 -> -83842484
B38: Mezzanine Principal Repayment ($) | C38: =MAX(0,MIN(C35,C37-C51)) -> 251906.21 | D38: =MAX(0,MIN(D35,D37-D51)) -> 7160286 | E38: =MAX(0,MIN(E35,E37-E51)) -> 614023.57 | F38: =MAX(0,MIN(F35,F37-F51)) -> 0 | G38: =MAX(0,MIN(G35,G37-G51)) -> 0 | H38: =MAX(0,MIN(H35,H37-H51)) -> 0 | I38: =MAX(0,MIN(I35,I37-I51)) -> 0 | J38: =MAX(0,MIN(J35,J37-J51)) -> 0 | ... U38: =MAX(0,MIN(U35,U37-U51)) -> 0 | V38: =V35 -> 62028947
B39: Mezzanine Total Debt Service, Cash Basis ($, = cash interest + principal) | C39: =C51+C38 -> 2506768.8 | D39: =D51+D38 -> 9397515.1 | E39: =E51+E38 -> 2350032.7 | F39: =F51+F38 -> 1687685.1 | G39: =G51+G38 -> 85225.519 | H39: =H51+H38 -> 825875.83 | I39: =I51+I38 -> 251928.41 | J39: =J51+J38 -> 562543.87 | ... V39: =V51+V38 -> 66370973
B40: Mezzanine Closing Balance ($) | C40: =C35+C52-C38 -> 31960416 | D40: =D35+D52-D38 -> 24800130 | E40: =E35+E52-E38 -> 24186107 | F40: =F35+F52-F38 -> 24191449 | G40: =G35+G52-G38 -> 25799625 | H40: =H35+H52-H38 -> 26779723 | I40: =I35+I52-I38 -> 28402375 | J40: =J35+J52-J38 -> 29827998 | ... V40: =V35+V52-V38 -> 0
B42: Leverage Covenant & Rolling Loan Life Coverage
B43: Annualised EBITDA ($, = period EBITDA x 2) | C43: =Operations!C44*2 -> 48587469 | D43: =Operations!D44*2 -> 28818233 | E43: =Operations!E44*2 -> 26362365 | F43: =Operations!F44*2 -> 24889588 | G43: =Operations!G44*2 -> 21490361 | H43: =Operations!H44*2 -> 20354237 | I43: =Operations!I44*2 -> 19163099 | J43: =Operations!J44*2 -> 17914948 | ... V43: =Operations!V44*2 -> -2927822
B44: Senior Leverage (Opening Senior Debt / Annualised EBITDA) (x) | C44: =C8/C43 -> 2.6041864 | D44: =D8/D43 -> 3.9507471 | E44: =E8/E43 -> 4.1034884 | F44: =F8/F43 -> 4.145377 | G44: =G8/G43 -> 4.5836689 | H44: =H8/H43 -> 4.6633116 | I44: =I8/I43 -> 4.7799268 | J44: =J8/J43 -> 4.9444018 | ... V44: =V8/V43 -> -27.403377
B45: Total Leverage incl. Mezz (x) | C45: =(C8+C35)/C43 -> 3.2671623 | D45: =(D8+D35)/D43 -> 5.0597816 | E45: =(E8+E35)/E43 -> 5.0442283 | F45: =(F8+F35)/F43 -> 5.1171129 | G45: =(G8+G35)/G43 -> 5.7093572 | H45: =(H8+H35)/H43 -> 5.9308426 | I45: =(I8+I35)/I43 -> 6.1773899 | J45: =(J8+J35)/J43 -> 6.5298027 | ... V45: =(V8+V35)/V43 -> -48.589415
B46: Maximum leverage covenant (x) | C46: =Assumptions!$F$82 -> 5 | D46: =Assumptions!$F$82 -> 5 | E46: =Assumptions!$F$82 -> 5 | F46: =Assumptions!$F$82 -> 5 | G46: =Assumptions!$F$82 -> 5 | H46: =Assumptions!$F$82 -> 5 | I46: =Assumptions!$F$82 -> 5 | J46: =Assumptions!$F$82 -> 5 | ... V46: =Assumptions!$F$82 -> 5
B47: Check: Leverage <= covenant maximum | C47: =IF(C44<=C46,"OK","REVIEW") -> OK | D47: =IF(D44<=D46,"OK","REVIEW") -> OK | E47: =IF(E44<=E46,"OK","REVIEW") -> OK | F47: =IF(F44<=F46,"OK","REVIEW") -> OK | G47: =IF(G44<=G46,"OK","REVIEW") -> OK | H47: =IF(H44<=H46,"OK","REVIEW") -> OK | I47: =IF(I44<=I46,"OK","REVIEW") -> OK | J47: =IF(J44<=J46,"OK","REVIEW") -> OK | ... V47: =IF(V44<=V46,"OK","REVIEW") -> OK
...

Sheet Waterfall
B2: Cash Flow Waterfall
B4: Priority of payments: Opex/Cash Tax (in Operations) -> Senior Debt Service -> Mezzanine Debt Service -> DSRA & MRA top-up/(release) -> VAT bridge one-off cost -> Net working-capital funding & revolver interest -> Distribution lock-up test -> Equity Distributions (gross of dividend withholding tax, applied on Outputs).
B5: Active Scenario: | C5: =Cover!$C$9 -> Base | D5: <<<< Cover
B6: Waterfall (Semi-Annual)
B7: CFADS ($) [from Operations] | C7: =Operations!C50 -> 24293734 | D7: =Operations!D50 -> 14409116 | E7: =Operations!E50 -> 13181182 | F7: =Operations!F50 -> 12444794 | G7: =Operations!G50 -> 10745181 | H7: =Operations!H50 -> 10177119 | I7: =Operations!I50 -> 9581549.4 | J7: =Operations!J50 -> 8957474.1 | ... V7: =Operations!V50 -> -1463911
B8: Less: Total Senior Debt Service ($) [from Debt] | C8: =Debt!C13 -> 18687488 | D8: =Debt!D13 -> 11083936 | E8: =Debt!E13 -> 10139371 | F8: =Debt!F13 -> 9572918.5 | G8: =Debt!G13 -> 8265523.6 | H8: =Debt!H13 -> 7828552.7 | I8: =Debt!I13 -> 7370422.6 | J8: =Debt!J13 -> 6890364.7 | ... V8: =Debt!V13 -> 84043240
B9: Cash Flow after Debt Service ($) | C9: =C7-C8 -> 5606246.4 | D9: =D7-D8 -> 3325180.7 | E9: =E7-E8 -> 3041811.3 | F9: =F7-F8 -> 2871875.6 | G9: =G7-G8 -> 2479657.1 | H9: =H7-H8 -> 2348565.8 | I9: =I7-I8 -> 2211126.8 | J9: =J7-J8 -> 2067109.4 | ... V9: =V7-V8 -> -85507151
B10: Less/(Plus): DSRA Movement — top-up/(release) ($) [from Reserves] | C10: =Reserves!C11 -> 0 | D10: =Reserves!D11 -> -7603552.2 | E10: =Reserves!E11 -> -944564.63 | F10: =Reserves!F11 -> -566452.61 | G10: =Reserves!G11 -> -1307394.9 | H10: =Reserves!H11 -> -436970.93 | I10: =Reserves!I11 -> -458130.1 | J10: =Reserves!J11 -> -480057.91 | ... V10: =Reserves!V11 -> -3811030
B11: Cash Available for Distribution ($) | C11: =C9-C10 -> 5606246.4 | D11: =D9-D10 -> 10928733 | E11: =E9-E10 -> 3986376 | F11: =F9-F10 -> 3438328.2 | G11: =G9-G10 -> 3787052 | H11: =H9-H10 -> 2785536.7 | I11: =I9-I10 -> 2669256.9 | J11: =J9-J10 -> 2547167.3 | ... V11: =V9-V10 -> -81696121
B12: Equity Distribution ($) | C12: =IF(C27="TRAP",0,MAX(0,C26)+C28) -> 0 | D12: =IF(D27="TRAP",0,MAX(0,D26)+D28) -> 0 | E12: =IF(E27="TRAP",0,MAX(0,E26)+E28) -> 0 | F12: =IF(F27="TRAP",0,MAX(0,F26)+F28) -> 0 | G12: =IF(G27="TRAP",0,MAX(0,G26)+G28) -> 0 | H12: =IF(H27="TRAP",0,MAX(0,H26)+H28) -> 0 | I12: =IF(I27="TRAP",0,MAX(0,I26)+I28) -> 0 | J12: =IF(J27="TRAP",0,MAX(0,J26)+J28) -> 0 | ... V12: =IF(V27="TRAP",0,MAX(0,V26)+V28) -> 0
B13: Cash Shortfall Flag (<0 = additional equity support required) ($) | C13: =MIN(0,C26) -> 0 | D13: =MIN(0,D26) -> 0 | E13: =MIN(0,E26) -> 0 | F13: =MIN(0,F26) -> 0 | G13: =MIN(0,G26) -> 0 | H13: =MIN(0,H26) -> 0 | I13: =MIN(0,I26) -> 0 | J13: =MIN(0,J26) -> 0 | ... V13: =MIN(0,V26) -> -1.5021346e+08
